[2025-10-25T14:10:17.812+0200] {local_task_job_runner.py:123} INFO - ::group::Pre task execution logs
[2025-10-25T14:10:17.847+0200] {taskinstance.py:2612} INFO - Dependencies all met for dep_context=non-requeueable deps ti=<TaskInstance: dbt_hourly_refresh.run_dbt_models scheduled__2025-10-25T11:00:00+00:00 [queued]>
[2025-10-25T14:10:17.864+0200] {taskinstance.py:2612} INFO - Dependencies all met for dep_context=requeueable deps ti=<TaskInstance: dbt_hourly_refresh.run_dbt_models scheduled__2025-10-25T11:00:00+00:00 [queued]>
[2025-10-25T14:10:17.865+0200] {taskinstance.py:2865} INFO - Starting attempt 2 of 2
[2025-10-25T14:10:17.886+0200] {taskinstance.py:2888} INFO - Executing <Task(BashOperator): run_dbt_models> on 2025-10-25 11:00:00+00:00
[2025-10-25T14:10:17.902+0200] {standard_task_runner.py:104} INFO - Running: ['***', 'tasks', 'run', 'dbt_hourly_refresh', 'run_dbt_models', 'scheduled__2025-10-25T11:00:00+00:00', '--job-id', '44', '--raw', '--subdir', 'DAGS_FOLDER/dbt_hourly_refresh_dag.py', '--cfg-path', '/tmp/tmpud9qkdss']
[2025-10-25T14:10:17.908+0200] {standard_task_runner.py:105} INFO - Job 44: Subtask run_dbt_models
[2025-10-25T14:10:17.909+0200] {logging_mixin.py:190} WARNING - /home/***/.local/lib/python3.12/site-packages/***/task/task_runner/standard_task_runner.py:70 DeprecationWarning: This process (pid=574) is multi-threaded, use of fork() may lead to deadlocks in the child.
[2025-10-25T14:10:17.910+0200] {standard_task_runner.py:72} INFO - Started process 578 to run task
[2025-10-25T14:10:18.030+0200] {task_command.py:467} INFO - Running <TaskInstance: dbt_hourly_refresh.run_dbt_models scheduled__2025-10-25T11:00:00+00:00 [running]> on host dae0b9df8402
[2025-10-25T14:10:18.221+0200] {taskinstance.py:3131} INFO - Exporting env vars: AIRFLOW_CTX_DAG_OWNER='Aliostadi' AIRFLOW_CTX_DAG_ID='dbt_hourly_refresh' AIRFLOW_CTX_TASK_ID='run_dbt_models' AIRFLOW_CTX_EXECUTION_DATE='2025-10-25T11:00:00+00:00' AIRFLOW_CTX_TRY_NUMBER='2' AIRFLOW_CTX_DAG_RUN_ID='scheduled__2025-10-25T11:00:00+00:00'
[2025-10-25T14:10:18.222+0200] {taskinstance.py:731} INFO - ::endgroup::
[2025-10-25T14:10:18.338+0200] {subprocess.py:63} INFO - Tmp dir root location: /tmp
[2025-10-25T14:10:18.341+0200] {subprocess.py:75} INFO - Running command: ['/usr/bin/bash', '-c', 'cd /opt/***/dbt_project && dbt clean && dbt run --full-refresh']
[2025-10-25T14:10:18.368+0200] {subprocess.py:86} INFO - Output:
[2025-10-25T14:10:26.639+0200] {subprocess.py:93} INFO - [0m12:10:26  Running with dbt=1.8.3
[2025-10-25T14:10:27.860+0200] {subprocess.py:93} INFO - [0m12:10:27  Checking /opt/***/dbt_project/target/*
[2025-10-25T14:10:27.879+0200] {subprocess.py:93} INFO - [0m12:10:27  Cleaned /opt/***/dbt_project/target/*
[2025-10-25T14:10:27.880+0200] {subprocess.py:93} INFO - [0m12:10:27  Checking /opt/***/dbt_project/dbt_packages/*
[2025-10-25T14:10:27.881+0200] {subprocess.py:93} INFO - [0m12:10:27  Cleaned /opt/***/dbt_project/dbt_packages/*
[2025-10-25T14:10:27.882+0200] {subprocess.py:93} INFO - [0m12:10:27  Finished cleaning all paths.
[2025-10-25T14:10:35.247+0200] {subprocess.py:93} INFO - [0m12:10:35  Running with dbt=1.8.3
[2025-10-25T14:10:36.497+0200] {subprocess.py:93} INFO - [0m12:10:36  Registered adapter: postgres=1.8.2
[2025-10-25T14:10:37.023+0200] {subprocess.py:93} INFO - [0m12:10:37  Unable to do partial parsing because saved manifest not found. Starting full parse.
[2025-10-25T14:10:38.859+0200] {subprocess.py:93} INFO - [0m12:10:38  [[33mWARNING[0m]: Deprecated functionality
[2025-10-25T14:10:38.860+0200] {subprocess.py:93} INFO - The `tests` config has been renamed to `data_tests`. Please see
[2025-10-25T14:10:38.860+0200] {subprocess.py:93} INFO - https://docs.getdbt.com/docs/build/data-tests#new-data_tests-syntax for more
[2025-10-25T14:10:38.860+0200] {subprocess.py:93} INFO - information.
[2025-10-25T14:10:39.752+0200] {subprocess.py:93} INFO - [0m12:10:39  [[33mWARNING[0m]: Configuration paths exist in your dbt_project.yml file which do not apply to any resources.
[2025-10-25T14:10:39.757+0200] {subprocess.py:93} INFO - There are 1 unused configuration paths:
[2025-10-25T14:10:39.758+0200] {subprocess.py:93} INFO - - models.intermediters
[2025-10-25T14:10:40.330+0200] {subprocess.py:93} INFO - [0m12:10:40  Found 3 models, 6 data tests, 3 sources, 428 macros
[2025-10-25T14:10:40.340+0200] {subprocess.py:93} INFO - [0m12:10:40
[2025-10-25T14:10:42.169+0200] {subprocess.py:93} INFO - [0m12:10:42  Concurrency: 4 threads (target='dev')
[2025-10-25T14:10:42.183+0200] {subprocess.py:93} INFO - [0m12:10:42
[2025-10-25T14:10:42.275+0200] {subprocess.py:93} INFO - [0m12:10:42  1 of 3 START sql incremental model analytics.int_performance_station_hour ...... [RUN]
[2025-10-25T14:10:42.279+0200] {subprocess.py:93} INFO - [0m12:10:42  2 of 3 START sql incremental model analytics.int_quality_station_hour .......... [RUN]
[2025-10-25T14:10:42.393+0200] {subprocess.py:93} INFO - [0m12:10:42  [31mUnhandled error while executing [0m
[2025-10-25T14:10:42.396+0200] {subprocess.py:93} INFO - [Errno 13] Permission denied: '/opt/***/dbt_project/target/compiled/smt_project/models/intermediate/int_performance_station_hour.sql'
[2025-10-25T14:10:42.400+0200] {subprocess.py:93} INFO - [0m12:10:42  [31mUnhandled error while executing [0m
[2025-10-25T14:10:42.401+0200] {subprocess.py:93} INFO - [Errno 13] Permission denied: '/opt/***/dbt_project/target/compiled/smt_project/models/intermediate/int_quality_station_hour.sql'
[2025-10-25T14:10:42.469+0200] {subprocess.py:93} INFO - [0m12:10:42  2 of 3 ERROR creating sql incremental model analytics.int_quality_station_hour . [[31mERROR[0m in 0.18s]
[2025-10-25T14:10:42.472+0200] {subprocess.py:93} INFO - [0m12:10:42  1 of 3 ERROR creating sql incremental model analytics.int_performance_station_hour  [[31mERROR[0m in 0.17s]
[2025-10-25T14:10:42.494+0200] {subprocess.py:93} INFO - [0m12:10:42  3 of 3 SKIP relation analytics.int_quality_linewise_datehour ................... [[33mSKIP[0m]
[2025-10-25T14:10:42.937+0200] {subprocess.py:93} INFO - [0m12:10:42
[2025-10-25T14:10:42.946+0200] {subprocess.py:93} INFO - [0m12:10:42  Finished running 3 incremental models in 0 hours 0 minutes and 2.59 seconds (2.59s).
[2025-10-25T14:10:43.099+0200] {subprocess.py:93} INFO - [0m12:10:43
[2025-10-25T14:10:43.102+0200] {subprocess.py:93} INFO - [0m12:10:43  [31mCompleted with 2 errors and 0 warnings:[0m
[2025-10-25T14:10:43.103+0200] {subprocess.py:93} INFO - [0m12:10:43
[2025-10-25T14:10:43.106+0200] {subprocess.py:93} INFO - [0m12:10:43    [Errno 13] Permission denied: '/opt/***/dbt_project/target/compiled/smt_project/models/intermediate/int_quality_station_hour.sql'
[2025-10-25T14:10:43.107+0200] {subprocess.py:93} INFO - [0m12:10:43
[2025-10-25T14:10:43.110+0200] {subprocess.py:93} INFO - [0m12:10:43    [Errno 13] Permission denied: '/opt/***/dbt_project/target/compiled/smt_project/models/intermediate/int_performance_station_hour.sql'
[2025-10-25T14:10:43.112+0200] {subprocess.py:93} INFO - [0m12:10:43
[2025-10-25T14:10:43.116+0200] {subprocess.py:93} INFO - [0m12:10:43  Done. PASS=0 WARN=0 ERROR=2 SKIP=1 TOTAL=3
[2025-10-25T14:10:44.291+0200] {subprocess.py:97} INFO - Command exited with return code 1
[2025-10-25T14:10:44.617+0200] {taskinstance.py:3310} ERROR - Task failed with exception
Traceback (most recent call last):
  File "/home/airflow/.local/lib/python3.12/site-packages/airflow/models/taskinstance.py", line 767, in _execute_task
    result = _execute_callable(context=context, **execute_callable_kwargs)
             ^^^^^^^^^^^^^^^^^^^^^^^^^^^^^^^^^^^^^^^^^^^^^^^^^^^^^^^^^^^^^
  File "/home/airflow/.local/lib/python3.12/site-packages/airflow/models/taskinstance.py", line 733, in _execute_callable
    return ExecutionCallableRunner(
           ^^^^^^^^^^^^^^^^^^^^^^^^
  File "/home/airflow/.local/lib/python3.12/site-packages/airflow/utils/operator_helpers.py", line 252, in run
    return self.func(*args, **kwargs)
           ^^^^^^^^^^^^^^^^^^^^^^^^^^
  File "/home/airflow/.local/lib/python3.12/site-packages/airflow/models/baseoperator.py", line 406, in wrapper
    return func(self, *args, **kwargs)
           ^^^^^^^^^^^^^^^^^^^^^^^^^^^
  File "/home/airflow/.local/lib/python3.12/site-packages/airflow/operators/bash.py", line 249, in execute
    raise AirflowException(
airflow.exceptions.AirflowException: Bash command failed. The command returned a non-zero exit code 1.
[2025-10-25T14:10:44.661+0200] {taskinstance.py:1225} INFO - Marking task as FAILED. dag_id=dbt_hourly_refresh, task_id=run_dbt_models, run_id=scheduled__2025-10-25T11:00:00+00:00, execution_date=20251025T110000, start_date=20251025T121017, end_date=20251025T121044
[2025-10-25T14:10:44.721+0200] {taskinstance.py:340} INFO - ::group::Post task execution logs
[2025-10-25T14:10:44.723+0200] {standard_task_runner.py:124} ERROR - Failed to execute job 44 for task run_dbt_models (Bash command failed. The command returned a non-zero exit code 1.; 578)
Traceback (most recent call last):
  File "/home/airflow/.local/lib/python3.12/site-packages/airflow/task/task_runner/standard_task_runner.py", line 117, in _start_by_fork
    ret = args.func(args, dag=self.dag)
          ^^^^^^^^^^^^^^^^^^^^^^^^^^^^^
  File "/home/airflow/.local/lib/python3.12/site-packages/airflow/cli/cli_config.py", line 49, in command
    return func(*args, **kwargs)
           ^^^^^^^^^^^^^^^^^^^^^
  File "/home/airflow/.local/lib/python3.12/site-packages/airflow/utils/cli.py", line 115, in wrapper
    return f(*args, **kwargs)
           ^^^^^^^^^^^^^^^^^^
  File "/home/airflow/.local/lib/python3.12/site-packages/airflow/cli/commands/task_command.py", line 483, in task_run
    task_return_code = _run_task_by_selected_method(args, _dag, ti)
                       ^^^^^^^^^^^^^^^^^^^^^^^^^^^^^^^^^^^^^^^^^^^^
  File "/home/airflow/.local/lib/python3.12/site-packages/airflow/cli/commands/task_command.py", line 256, in _run_task_by_selected_method
    return _run_raw_task(args, ti)
           ^^^^^^^^^^^^^^^^^^^^^^^
  File "/home/airflow/.local/lib/python3.12/site-packages/airflow/cli/commands/task_command.py", line 341, in _run_raw_task
    return ti._run_raw_task(
           ^^^^^^^^^^^^^^^^^
  File "/home/airflow/.local/lib/python3.12/site-packages/airflow/utils/session.py", line 97, in wrapper
    return func(*args, session=session, **kwargs)
           ^^^^^^^^^^^^^^^^^^^^^^^^^^^^^^^^^^^^^^
  File "/home/airflow/.local/lib/python3.12/site-packages/airflow/models/taskinstance.py", line 3004, in _run_raw_task
    return _run_raw_task(
           ^^^^^^^^^^^^^^
  File "/home/airflow/.local/lib/python3.12/site-packages/airflow/models/taskinstance.py", line 273, in _run_raw_task
    TaskInstance._execute_task_with_callbacks(
  File "/home/airflow/.local/lib/python3.12/site-packages/airflow/models/taskinstance.py", line 3158, in _execute_task_with_callbacks
    result = self._execute_task(context, task_orig)
             ^^^^^^^^^^^^^^^^^^^^^^^^^^^^^^^^^^^^^^
  File "/home/airflow/.local/lib/python3.12/site-packages/airflow/models/taskinstance.py", line 3182, in _execute_task
    return _execute_task(self, context, task_orig)
           ^^^^^^^^^^^^^^^^^^^^^^^^^^^^^^^^^^^^^^^
  File "/home/airflow/.local/lib/python3.12/site-packages/airflow/models/taskinstance.py", line 767, in _execute_task
    result = _execute_callable(context=context, **execute_callable_kwargs)
             ^^^^^^^^^^^^^^^^^^^^^^^^^^^^^^^^^^^^^^^^^^^^^^^^^^^^^^^^^^^^^
  File "/home/airflow/.local/lib/python3.12/site-packages/airflow/models/taskinstance.py", line 733, in _execute_callable
    return ExecutionCallableRunner(
           ^^^^^^^^^^^^^^^^^^^^^^^^
  File "/home/airflow/.local/lib/python3.12/site-packages/airflow/utils/operator_helpers.py", line 252, in run
    return self.func(*args, **kwargs)
           ^^^^^^^^^^^^^^^^^^^^^^^^^^
  File "/home/airflow/.local/lib/python3.12/site-packages/airflow/models/baseoperator.py", line 406, in wrapper
    return func(self, *args, **kwargs)
           ^^^^^^^^^^^^^^^^^^^^^^^^^^^
  File "/home/airflow/.local/lib/python3.12/site-packages/airflow/operators/bash.py", line 249, in execute
    raise AirflowException(
airflow.exceptions.AirflowException: Bash command failed. The command returned a non-zero exit code 1.
[2025-10-25T14:10:44.771+0200] {local_task_job_runner.py:266} INFO - Task exited with return code 1
[2025-10-25T14:10:44.849+0200] {taskinstance.py:3900} INFO - 0 downstream tasks scheduled from follow-on schedule check
[2025-10-25T14:10:44.852+0200] {local_task_job_runner.py:245} INFO - ::endgroup::
