[2025-10-25T14:00:01.436+0200] {local_task_job_runner.py:123} INFO - ::group::Pre task execution logs
[2025-10-25T14:00:01.486+0200] {taskinstance.py:2612} INFO - Dependencies all met for dep_context=non-requeueable deps ti=<TaskInstance: dbt_hourly_refresh.run_dbt_models scheduled__2025-10-25T11:00:00+00:00 [queued]>
[2025-10-25T14:00:01.506+0200] {taskinstance.py:2612} INFO - Dependencies all met for dep_context=requeueable deps ti=<TaskInstance: dbt_hourly_refresh.run_dbt_models scheduled__2025-10-25T11:00:00+00:00 [queued]>
[2025-10-25T14:00:01.506+0200] {taskinstance.py:2865} INFO - Starting attempt 1 of 2
[2025-10-25T14:00:01.533+0200] {taskinstance.py:2888} INFO - Executing <Task(BashOperator): run_dbt_models> on 2025-10-25 11:00:00+00:00
[2025-10-25T14:00:01.548+0200] {standard_task_runner.py:104} INFO - Running: ['***', 'tasks', 'run', 'dbt_hourly_refresh', 'run_dbt_models', 'scheduled__2025-10-25T11:00:00+00:00', '--job-id', '40', '--raw', '--subdir', 'DAGS_FOLDER/dbt_hourly_refresh_dag.py', '--cfg-path', '/tmp/tmp3n9iwdak']
[2025-10-25T14:00:01.554+0200] {standard_task_runner.py:105} INFO - Job 40: Subtask run_dbt_models
[2025-10-25T14:00:01.555+0200] {logging_mixin.py:190} WARNING - /home/***/.local/lib/python3.12/site-packages/***/task/task_runner/standard_task_runner.py:70 DeprecationWarning: This process (pid=406) is multi-threaded, use of fork() may lead to deadlocks in the child.
[2025-10-25T14:00:01.556+0200] {standard_task_runner.py:72} INFO - Started process 407 to run task
[2025-10-25T14:00:01.663+0200] {task_command.py:467} INFO - Running <TaskInstance: dbt_hourly_refresh.run_dbt_models scheduled__2025-10-25T11:00:00+00:00 [running]> on host dae0b9df8402
[2025-10-25T14:00:01.793+0200] {taskinstance.py:3131} INFO - Exporting env vars: AIRFLOW_CTX_DAG_OWNER='Aliostadi' AIRFLOW_CTX_DAG_ID='dbt_hourly_refresh' AIRFLOW_CTX_TASK_ID='run_dbt_models' AIRFLOW_CTX_EXECUTION_DATE='2025-10-25T11:00:00+00:00' AIRFLOW_CTX_TRY_NUMBER='1' AIRFLOW_CTX_DAG_RUN_ID='scheduled__2025-10-25T11:00:00+00:00'
[2025-10-25T14:00:01.793+0200] {taskinstance.py:731} INFO - ::endgroup::
[2025-10-25T14:00:01.845+0200] {subprocess.py:63} INFO - Tmp dir root location: /tmp
[2025-10-25T14:00:01.846+0200] {subprocess.py:75} INFO - Running command: ['/usr/bin/bash', '-c', 'cd /opt/***/dbt_project && dbt clean && dbt run --full-refresh']
[2025-10-25T14:00:01.867+0200] {subprocess.py:86} INFO - Output:
[2025-10-25T14:00:06.909+0200] {subprocess.py:93} INFO - [0m12:00:06  Running with dbt=1.8.3
[2025-10-25T14:00:07.228+0200] {subprocess.py:93} INFO - [0m12:00:07  Checking /opt/***/dbt_project/dbt_packages/*
[2025-10-25T14:00:07.228+0200] {subprocess.py:93} INFO - [0m12:00:07  Cleaned /opt/***/dbt_project/dbt_packages/*
[2025-10-25T14:00:07.229+0200] {subprocess.py:93} INFO - [0m12:00:07  Checking /opt/***/dbt_project/target/*
[2025-10-25T14:00:07.237+0200] {subprocess.py:93} INFO - [0m12:00:07  Cleaned /opt/***/dbt_project/target/*
[2025-10-25T14:00:07.239+0200] {subprocess.py:93} INFO - [0m12:00:07  Finished cleaning all paths.
[2025-10-25T14:00:12.145+0200] {subprocess.py:93} INFO - [0m12:00:12  Running with dbt=1.8.3
[2025-10-25T14:00:12.794+0200] {subprocess.py:93} INFO - [0m12:00:12  Registered adapter: postgres=1.8.2
[2025-10-25T14:00:12.992+0200] {subprocess.py:93} INFO - [0m12:00:12  Unable to do partial parsing because saved manifest not found. Starting full parse.
[2025-10-25T14:00:14.780+0200] {subprocess.py:93} INFO - [0m12:00:14  [[33mWARNING[0m]: Deprecated functionality
[2025-10-25T14:00:14.781+0200] {subprocess.py:93} INFO - The `tests` config has been renamed to `data_tests`. Please see
[2025-10-25T14:00:14.781+0200] {subprocess.py:93} INFO - https://docs.getdbt.com/docs/build/data-tests#new-data_tests-syntax for more
[2025-10-25T14:00:14.782+0200] {subprocess.py:93} INFO - information.
[2025-10-25T14:00:15.732+0200] {subprocess.py:93} INFO - [0m12:00:15  [[33mWARNING[0m]: Configuration paths exist in your dbt_project.yml file which do not apply to any resources.
[2025-10-25T14:00:15.734+0200] {subprocess.py:93} INFO - There are 1 unused configuration paths:
[2025-10-25T14:00:15.735+0200] {subprocess.py:93} INFO - - models.intermediters
[2025-10-25T14:00:16.092+0200] {subprocess.py:93} INFO - [0m12:00:16  Found 3 models, 6 data tests, 3 sources, 428 macros
[2025-10-25T14:00:16.095+0200] {subprocess.py:93} INFO - [0m12:00:16
[2025-10-25T14:00:16.349+0200] {subprocess.py:93} INFO - [0m12:00:16  Concurrency: 4 threads (target='dev')
[2025-10-25T14:00:16.349+0200] {subprocess.py:93} INFO - [0m12:00:16
[2025-10-25T14:00:16.365+0200] {subprocess.py:93} INFO - [0m12:00:16  1 of 3 START sql incremental model analytics.int_performance_station_hour ...... [RUN]
[2025-10-25T14:00:16.368+0200] {subprocess.py:93} INFO - [0m12:00:16  2 of 3 START sql incremental model analytics.int_quality_station_hour .......... [RUN]
[2025-10-25T14:00:16.389+0200] {subprocess.py:93} INFO - [0m12:00:16  [31mUnhandled error while executing [0m
[2025-10-25T14:00:16.390+0200] {subprocess.py:93} INFO - [Errno 13] Permission denied: '/opt/***/dbt_project/target/compiled/smt_project/models/intermediate/int_performance_station_hour.sql'
[2025-10-25T14:00:16.399+0200] {subprocess.py:93} INFO - [0m12:00:16  [31mUnhandled error while executing [0m
[2025-10-25T14:00:16.399+0200] {subprocess.py:93} INFO - [Errno 13] Permission denied: '/opt/***/dbt_project/target/compiled/smt_project/models/intermediate/int_quality_station_hour.sql'
[2025-10-25T14:00:16.414+0200] {subprocess.py:93} INFO - [0m12:00:16  2 of 3 ERROR creating sql incremental model analytics.int_quality_station_hour . [[31mERROR[0m in 0.04s]
[2025-10-25T14:00:16.415+0200] {subprocess.py:93} INFO - [0m12:00:16  1 of 3 ERROR creating sql incremental model analytics.int_performance_station_hour  [[31mERROR[0m in 0.05s]
[2025-10-25T14:00:16.421+0200] {subprocess.py:93} INFO - [0m12:00:16  3 of 3 SKIP relation analytics.int_quality_linewise_datehour ................... [[33mSKIP[0m]
[2025-10-25T14:00:16.451+0200] {subprocess.py:93} INFO - [0m12:00:16
[2025-10-25T14:00:16.452+0200] {subprocess.py:93} INFO - [0m12:00:16  Finished running 3 incremental models in 0 hours 0 minutes and 0.35 seconds (0.35s).
[2025-10-25T14:00:16.491+0200] {subprocess.py:93} INFO - [0m12:00:16
[2025-10-25T14:00:16.491+0200] {subprocess.py:93} INFO - [0m12:00:16  [31mCompleted with 2 errors and 0 warnings:[0m
[2025-10-25T14:00:16.492+0200] {subprocess.py:93} INFO - [0m12:00:16
[2025-10-25T14:00:16.493+0200] {subprocess.py:93} INFO - [0m12:00:16    [Errno 13] Permission denied: '/opt/***/dbt_project/target/compiled/smt_project/models/intermediate/int_quality_station_hour.sql'
[2025-10-25T14:00:16.493+0200] {subprocess.py:93} INFO - [0m12:00:16
[2025-10-25T14:00:16.494+0200] {subprocess.py:93} INFO - [0m12:00:16    [Errno 13] Permission denied: '/opt/***/dbt_project/target/compiled/smt_project/models/intermediate/int_performance_station_hour.sql'
[2025-10-25T14:00:16.494+0200] {subprocess.py:93} INFO - [0m12:00:16
[2025-10-25T14:00:16.495+0200] {subprocess.py:93} INFO - [0m12:00:16  Done. PASS=0 WARN=0 ERROR=2 SKIP=1 TOTAL=3
[2025-10-25T14:00:16.822+0200] {subprocess.py:97} INFO - Command exited with return code 1
[2025-10-25T14:00:16.838+0200] {taskinstance.py:3310} ERROR - Task failed with exception
Traceback (most recent call last):
  File "/home/airflow/.local/lib/python3.12/site-packages/airflow/models/taskinstance.py", line 767, in _execute_task
    result = _execute_callable(context=context, **execute_callable_kwargs)
             ^^^^^^^^^^^^^^^^^^^^^^^^^^^^^^^^^^^^^^^^^^^^^^^^^^^^^^^^^^^^^
  File "/home/airflow/.local/lib/python3.12/site-packages/airflow/models/taskinstance.py", line 733, in _execute_callable
    return ExecutionCallableRunner(
           ^^^^^^^^^^^^^^^^^^^^^^^^
  File "/home/airflow/.local/lib/python3.12/site-packages/airflow/utils/operator_helpers.py", line 252, in run
    return self.func(*args, **kwargs)
           ^^^^^^^^^^^^^^^^^^^^^^^^^^
  File "/home/airflow/.local/lib/python3.12/site-packages/airflow/models/baseoperator.py", line 406, in wrapper
    return func(self, *args, **kwargs)
           ^^^^^^^^^^^^^^^^^^^^^^^^^^^
  File "/home/airflow/.local/lib/python3.12/site-packages/airflow/operators/bash.py", line 249, in execute
    raise AirflowException(
airflow.exceptions.AirflowException: Bash command failed. The command returned a non-zero exit code 1.
[2025-10-25T14:00:16.853+0200] {taskinstance.py:1225} INFO - Marking task as UP_FOR_RETRY. dag_id=dbt_hourly_refresh, task_id=run_dbt_models, run_id=scheduled__2025-10-25T11:00:00+00:00, execution_date=20251025T110000, start_date=20251025T120001, end_date=20251025T120016
[2025-10-25T14:00:16.873+0200] {taskinstance.py:340} INFO - ::group::Post task execution logs
[2025-10-25T14:00:16.873+0200] {standard_task_runner.py:124} ERROR - Failed to execute job 40 for task run_dbt_models (Bash command failed. The command returned a non-zero exit code 1.; 407)
Traceback (most recent call last):
  File "/home/airflow/.local/lib/python3.12/site-packages/airflow/task/task_runner/standard_task_runner.py", line 117, in _start_by_fork
    ret = args.func(args, dag=self.dag)
          ^^^^^^^^^^^^^^^^^^^^^^^^^^^^^
  File "/home/airflow/.local/lib/python3.12/site-packages/airflow/cli/cli_config.py", line 49, in command
    return func(*args, **kwargs)
           ^^^^^^^^^^^^^^^^^^^^^
  File "/home/airflow/.local/lib/python3.12/site-packages/airflow/utils/cli.py", line 115, in wrapper
    return f(*args, **kwargs)
           ^^^^^^^^^^^^^^^^^^
  File "/home/airflow/.local/lib/python3.12/site-packages/airflow/cli/commands/task_command.py", line 483, in task_run
    task_return_code = _run_task_by_selected_method(args, _dag, ti)
                       ^^^^^^^^^^^^^^^^^^^^^^^^^^^^^^^^^^^^^^^^^^^^
  File "/home/airflow/.local/lib/python3.12/site-packages/airflow/cli/commands/task_command.py", line 256, in _run_task_by_selected_method
    return _run_raw_task(args, ti)
           ^^^^^^^^^^^^^^^^^^^^^^^
  File "/home/airflow/.local/lib/python3.12/site-packages/airflow/cli/commands/task_command.py", line 341, in _run_raw_task
    return ti._run_raw_task(
           ^^^^^^^^^^^^^^^^^
  File "/home/airflow/.local/lib/python3.12/site-packages/airflow/utils/session.py", line 97, in wrapper
    return func(*args, session=session, **kwargs)
           ^^^^^^^^^^^^^^^^^^^^^^^^^^^^^^^^^^^^^^
  File "/home/airflow/.local/lib/python3.12/site-packages/airflow/models/taskinstance.py", line 3004, in _run_raw_task
    return _run_raw_task(
           ^^^^^^^^^^^^^^
  File "/home/airflow/.local/lib/python3.12/site-packages/airflow/models/taskinstance.py", line 273, in _run_raw_task
    TaskInstance._execute_task_with_callbacks(
  File "/home/airflow/.local/lib/python3.12/site-packages/airflow/models/taskinstance.py", line 3158, in _execute_task_with_callbacks
    result = self._execute_task(context, task_orig)
             ^^^^^^^^^^^^^^^^^^^^^^^^^^^^^^^^^^^^^^
  File "/home/airflow/.local/lib/python3.12/site-packages/airflow/models/taskinstance.py", line 3182, in _execute_task
    return _execute_task(self, context, task_orig)
           ^^^^^^^^^^^^^^^^^^^^^^^^^^^^^^^^^^^^^^^
  File "/home/airflow/.local/lib/python3.12/site-packages/airflow/models/taskinstance.py", line 767, in _execute_task
    result = _execute_callable(context=context, **execute_callable_kwargs)
             ^^^^^^^^^^^^^^^^^^^^^^^^^^^^^^^^^^^^^^^^^^^^^^^^^^^^^^^^^^^^^
  File "/home/airflow/.local/lib/python3.12/site-packages/airflow/models/taskinstance.py", line 733, in _execute_callable
    return ExecutionCallableRunner(
           ^^^^^^^^^^^^^^^^^^^^^^^^
  File "/home/airflow/.local/lib/python3.12/site-packages/airflow/utils/operator_helpers.py", line 252, in run
    return self.func(*args, **kwargs)
           ^^^^^^^^^^^^^^^^^^^^^^^^^^
  File "/home/airflow/.local/lib/python3.12/site-packages/airflow/models/baseoperator.py", line 406, in wrapper
    return func(self, *args, **kwargs)
           ^^^^^^^^^^^^^^^^^^^^^^^^^^^
  File "/home/airflow/.local/lib/python3.12/site-packages/airflow/operators/bash.py", line 249, in execute
    raise AirflowException(
airflow.exceptions.AirflowException: Bash command failed. The command returned a non-zero exit code 1.
[2025-10-25T14:00:16.920+0200] {local_task_job_runner.py:266} INFO - Task exited with return code 1
[2025-10-25T14:00:16.945+0200] {taskinstance.py:3900} INFO - 0 downstream tasks scheduled from follow-on schedule check
[2025-10-25T14:00:16.949+0200] {local_task_job_runner.py:245} INFO - ::endgroup::
