[2025-10-24T00:49:53.160+0200] {local_task_job_runner.py:123} INFO - ::group::Pre task execution logs
[2025-10-24T00:49:53.198+0200] {taskinstance.py:2612} INFO - Dependencies all met for dep_context=non-requeueable deps ti=<TaskInstance: dbt_hourly_refresh.run_dbt_models manual__2025-10-23T22:39:41.184746+00:00 [queued]>
[2025-10-24T00:49:53.208+0200] {taskinstance.py:2612} INFO - Dependencies all met for dep_context=requeueable deps ti=<TaskInstance: dbt_hourly_refresh.run_dbt_models manual__2025-10-23T22:39:41.184746+00:00 [queued]>
[2025-10-24T00:49:53.208+0200] {taskinstance.py:2865} INFO - Starting attempt 2 of 2
[2025-10-24T00:49:53.223+0200] {taskinstance.py:2888} INFO - Executing <Task(BashOperator): run_dbt_models> on 2025-10-23 22:39:41.184746+00:00
[2025-10-24T00:49:53.235+0200] {standard_task_runner.py:104} INFO - Running: ['***', 'tasks', 'run', 'dbt_hourly_refresh', 'run_dbt_models', 'manual__2025-10-23T22:39:41.184746+00:00', '--job-id', '23', '--raw', '--subdir', 'DAGS_FOLDER/dbt_hourly_refresh_dag.py', '--cfg-path', '/tmp/tmpwg32shwv']
[2025-10-24T00:49:53.239+0200] {standard_task_runner.py:105} INFO - Job 23: Subtask run_dbt_models
[2025-10-24T00:49:53.239+0200] {logging_mixin.py:190} WARNING - /home/***/.local/lib/python3.12/site-packages/***/task/task_runner/standard_task_runner.py:70 DeprecationWarning: This process (pid=802) is multi-threaded, use of fork() may lead to deadlocks in the child.
[2025-10-24T00:49:53.240+0200] {standard_task_runner.py:72} INFO - Started process 803 to run task
[2025-10-24T00:49:53.307+0200] {task_command.py:467} INFO - Running <TaskInstance: dbt_hourly_refresh.run_dbt_models manual__2025-10-23T22:39:41.184746+00:00 [running]> on host 0552639bb6f4
[2025-10-24T00:49:53.448+0200] {taskinstance.py:3131} INFO - Exporting env vars: AIRFLOW_CTX_DAG_OWNER='Aliostadi' AIRFLOW_CTX_DAG_ID='dbt_hourly_refresh' AIRFLOW_CTX_TASK_ID='run_dbt_models' AIRFLOW_CTX_EXECUTION_DATE='2025-10-23T22:39:41.184746+00:00' AIRFLOW_CTX_TRY_NUMBER='2' AIRFLOW_CTX_DAG_RUN_ID='manual__2025-10-23T22:39:41.184746+00:00'
[2025-10-24T00:49:53.449+0200] {taskinstance.py:731} INFO - ::endgroup::
[2025-10-24T00:49:53.525+0200] {subprocess.py:63} INFO - Tmp dir root location: /tmp
[2025-10-24T00:49:53.527+0200] {subprocess.py:75} INFO - Running command: ['/usr/bin/bash', '-c', 'cd /opt/***/dbt_project && dbt run']
[2025-10-24T00:49:53.543+0200] {subprocess.py:86} INFO - Output:
[2025-10-24T00:49:57.862+0200] {subprocess.py:93} INFO - [0m22:49:57  Running with dbt=1.8.5
[2025-10-24T00:49:58.400+0200] {subprocess.py:93} INFO - [0m22:49:58  Registered adapter: postgres=1.8.2
[2025-10-24T00:49:58.825+0200] {subprocess.py:93} INFO - [0m22:49:58  [[33mWARNING[0m]: Configuration paths exist in your dbt_project.yml file which do not apply to any resources.
[2025-10-24T00:49:58.825+0200] {subprocess.py:93} INFO - There are 1 unused configuration paths:
[2025-10-24T00:49:58.825+0200] {subprocess.py:93} INFO - - models.intermediters
[2025-10-24T00:49:59.034+0200] {subprocess.py:93} INFO - [0m22:49:59  Found 3 models, 6 data tests, 3 sources, 428 macros
[2025-10-24T00:49:59.037+0200] {subprocess.py:93} INFO - [0m22:49:59
[2025-10-24T00:50:11.129+0200] {subprocess.py:93} INFO - [0m22:50:11
[2025-10-24T00:50:11.137+0200] {subprocess.py:93} INFO - [0m22:50:11  Finished running  in 0 hours 0 minutes and 12.09 seconds (12.09s).
[2025-10-24T00:50:11.137+0200] {subprocess.py:93} INFO - [0m22:50:11  Encountered an error:
[2025-10-24T00:50:11.138+0200] {subprocess.py:93} INFO - Database Error
[2025-10-24T00:50:11.138+0200] {subprocess.py:93} INFO -   could not translate host name "smt-postgres" to address: Name or service not known
[2025-10-24T00:50:11.138+0200] {subprocess.py:93} INFO - 
[2025-10-24T00:50:11.692+0200] {subprocess.py:97} INFO - Command exited with return code 2
[2025-10-24T00:50:11.714+0200] {taskinstance.py:3310} ERROR - Task failed with exception
Traceback (most recent call last):
  File "/home/airflow/.local/lib/python3.12/site-packages/airflow/models/taskinstance.py", line 767, in _execute_task
    result = _execute_callable(context=context, **execute_callable_kwargs)
             ^^^^^^^^^^^^^^^^^^^^^^^^^^^^^^^^^^^^^^^^^^^^^^^^^^^^^^^^^^^^^
  File "/home/airflow/.local/lib/python3.12/site-packages/airflow/models/taskinstance.py", line 733, in _execute_callable
    return ExecutionCallableRunner(
           ^^^^^^^^^^^^^^^^^^^^^^^^
  File "/home/airflow/.local/lib/python3.12/site-packages/airflow/utils/operator_helpers.py", line 252, in run
    return self.func(*args, **kwargs)
           ^^^^^^^^^^^^^^^^^^^^^^^^^^
  File "/home/airflow/.local/lib/python3.12/site-packages/airflow/models/baseoperator.py", line 406, in wrapper
    return func(self, *args, **kwargs)
           ^^^^^^^^^^^^^^^^^^^^^^^^^^^
  File "/home/airflow/.local/lib/python3.12/site-packages/airflow/operators/bash.py", line 249, in execute
    raise AirflowException(
airflow.exceptions.AirflowException: Bash command failed. The command returned a non-zero exit code 2.
[2025-10-24T00:50:11.730+0200] {taskinstance.py:1225} INFO - Marking task as FAILED. dag_id=dbt_hourly_refresh, task_id=run_dbt_models, run_id=manual__2025-10-23T22:39:41.184746+00:00, execution_date=20251023T223941, start_date=20251023T224953, end_date=20251023T225011
[2025-10-24T00:50:11.756+0200] {taskinstance.py:340} INFO - ::group::Post task execution logs
[2025-10-24T00:50:11.757+0200] {standard_task_runner.py:124} ERROR - Failed to execute job 23 for task run_dbt_models (Bash command failed. The command returned a non-zero exit code 2.; 803)
Traceback (most recent call last):
  File "/home/airflow/.local/lib/python3.12/site-packages/airflow/task/task_runner/standard_task_runner.py", line 117, in _start_by_fork
    ret = args.func(args, dag=self.dag)
          ^^^^^^^^^^^^^^^^^^^^^^^^^^^^^
  File "/home/airflow/.local/lib/python3.12/site-packages/airflow/cli/cli_config.py", line 49, in command
    return func(*args, **kwargs)
           ^^^^^^^^^^^^^^^^^^^^^
  File "/home/airflow/.local/lib/python3.12/site-packages/airflow/utils/cli.py", line 115, in wrapper
    return f(*args, **kwargs)
           ^^^^^^^^^^^^^^^^^^
  File "/home/airflow/.local/lib/python3.12/site-packages/airflow/cli/commands/task_command.py", line 483, in task_run
    task_return_code = _run_task_by_selected_method(args, _dag, ti)
                       ^^^^^^^^^^^^^^^^^^^^^^^^^^^^^^^^^^^^^^^^^^^^
  File "/home/airflow/.local/lib/python3.12/site-packages/airflow/cli/commands/task_command.py", line 256, in _run_task_by_selected_method
    return _run_raw_task(args, ti)
           ^^^^^^^^^^^^^^^^^^^^^^^
  File "/home/airflow/.local/lib/python3.12/site-packages/airflow/cli/commands/task_command.py", line 341, in _run_raw_task
    return ti._run_raw_task(
           ^^^^^^^^^^^^^^^^^
  File "/home/airflow/.local/lib/python3.12/site-packages/airflow/utils/session.py", line 97, in wrapper
    return func(*args, session=session, **kwargs)
           ^^^^^^^^^^^^^^^^^^^^^^^^^^^^^^^^^^^^^^
  File "/home/airflow/.local/lib/python3.12/site-packages/airflow/models/taskinstance.py", line 3004, in _run_raw_task
    return _run_raw_task(
           ^^^^^^^^^^^^^^
  File "/home/airflow/.local/lib/python3.12/site-packages/airflow/models/taskinstance.py", line 273, in _run_raw_task
    TaskInstance._execute_task_with_callbacks(
  File "/home/airflow/.local/lib/python3.12/site-packages/airflow/models/taskinstance.py", line 3158, in _execute_task_with_callbacks
    result = self._execute_task(context, task_orig)
             ^^^^^^^^^^^^^^^^^^^^^^^^^^^^^^^^^^^^^^
  File "/home/airflow/.local/lib/python3.12/site-packages/airflow/models/taskinstance.py", line 3182, in _execute_task
    return _execute_task(self, context, task_orig)
           ^^^^^^^^^^^^^^^^^^^^^^^^^^^^^^^^^^^^^^^
  File "/home/airflow/.local/lib/python3.12/site-packages/airflow/models/taskinstance.py", line 767, in _execute_task
    result = _execute_callable(context=context, **execute_callable_kwargs)
             ^^^^^^^^^^^^^^^^^^^^^^^^^^^^^^^^^^^^^^^^^^^^^^^^^^^^^^^^^^^^^
  File "/home/airflow/.local/lib/python3.12/site-packages/airflow/models/taskinstance.py", line 733, in _execute_callable
    return ExecutionCallableRunner(
           ^^^^^^^^^^^^^^^^^^^^^^^^
  File "/home/airflow/.local/lib/python3.12/site-packages/airflow/utils/operator_helpers.py", line 252, in run
    return self.func(*args, **kwargs)
           ^^^^^^^^^^^^^^^^^^^^^^^^^^
  File "/home/airflow/.local/lib/python3.12/site-packages/airflow/models/baseoperator.py", line 406, in wrapper
    return func(self, *args, **kwargs)
           ^^^^^^^^^^^^^^^^^^^^^^^^^^^
  File "/home/airflow/.local/lib/python3.12/site-packages/airflow/operators/bash.py", line 249, in execute
    raise AirflowException(
airflow.exceptions.AirflowException: Bash command failed. The command returned a non-zero exit code 2.
[2025-10-24T00:50:11.800+0200] {local_task_job_runner.py:266} INFO - Task exited with return code 1
[2025-10-24T00:50:11.844+0200] {taskinstance.py:3900} INFO - 0 downstream tasks scheduled from follow-on schedule check
[2025-10-24T00:50:11.846+0200] {local_task_job_runner.py:245} INFO - ::endgroup::
