[2025-10-25T15:07:26.647+0200] {local_task_job_runner.py:123} INFO - ::group::Pre task execution logs
[2025-10-25T15:07:26.679+0200] {taskinstance.py:2612} INFO - Dependencies all met for dep_context=non-requeueable deps ti=<TaskInstance: dbt_hourly_refresh.run_dbt_models scheduled__2025-10-25T12:00:00+00:00 [queued]>
[2025-10-25T15:07:26.694+0200] {taskinstance.py:2612} INFO - Dependencies all met for dep_context=requeueable deps ti=<TaskInstance: dbt_hourly_refresh.run_dbt_models scheduled__2025-10-25T12:00:00+00:00 [queued]>
[2025-10-25T15:07:26.695+0200] {taskinstance.py:2865} INFO - Starting attempt 1 of 2
[2025-10-25T15:07:26.710+0200] {taskinstance.py:2888} INFO - Executing <Task(BashOperator): run_dbt_models> on 2025-10-25 12:00:00+00:00
[2025-10-25T15:07:26.721+0200] {standard_task_runner.py:104} INFO - Running: ['***', 'tasks', 'run', 'dbt_hourly_refresh', 'run_dbt_models', 'scheduled__2025-10-25T12:00:00+00:00', '--job-id', '46', '--raw', '--subdir', 'DAGS_FOLDER/dbt_hourly_refresh_dag.py', '--cfg-path', '/tmp/tmpjct1x16w']
[2025-10-25T15:07:26.725+0200] {standard_task_runner.py:105} INFO - Job 46: Subtask run_dbt_models
[2025-10-25T15:07:26.725+0200] {logging_mixin.py:190} WARNING - /home/***/.local/lib/python3.12/site-packages/***/task/task_runner/standard_task_runner.py:70 DeprecationWarning: This process (pid=257) is multi-threaded, use of fork() may lead to deadlocks in the child.
[2025-10-25T15:07:26.726+0200] {standard_task_runner.py:72} INFO - Started process 260 to run task
[2025-10-25T15:07:26.802+0200] {task_command.py:467} INFO - Running <TaskInstance: dbt_hourly_refresh.run_dbt_models scheduled__2025-10-25T12:00:00+00:00 [running]> on host 197aef1bec7d
[2025-10-25T15:07:26.946+0200] {taskinstance.py:3131} INFO - Exporting env vars: AIRFLOW_CTX_DAG_OWNER='Aliostadi' AIRFLOW_CTX_DAG_ID='dbt_hourly_refresh' AIRFLOW_CTX_TASK_ID='run_dbt_models' AIRFLOW_CTX_EXECUTION_DATE='2025-10-25T12:00:00+00:00' AIRFLOW_CTX_TRY_NUMBER='1' AIRFLOW_CTX_DAG_RUN_ID='scheduled__2025-10-25T12:00:00+00:00'
[2025-10-25T15:07:26.947+0200] {taskinstance.py:731} INFO - ::endgroup::
[2025-10-25T15:07:27.045+0200] {subprocess.py:63} INFO - Tmp dir root location: /tmp
[2025-10-25T15:07:27.046+0200] {subprocess.py:75} INFO - Running command: ['/usr/bin/bash', '-c', 'cd /opt/***/dbt_project && dbt clean && dbt run --full-refresh']
[2025-10-25T15:07:27.059+0200] {subprocess.py:86} INFO - Output:
[2025-10-25T15:07:30.749+0200] {subprocess.py:93} INFO - [0m13:07:30  Running with dbt=1.8.3
[2025-10-25T15:07:30.995+0200] {subprocess.py:93} INFO - [0m13:07:30  Checking /opt/***/dbt_project/target/*
[2025-10-25T15:07:31.004+0200] {subprocess.py:93} INFO - [0m13:07:31  Cleaned /opt/***/dbt_project/target/*
[2025-10-25T15:07:31.004+0200] {subprocess.py:93} INFO - [0m13:07:31  Checking /opt/***/dbt_project/dbt_packages/*
[2025-10-25T15:07:31.004+0200] {subprocess.py:93} INFO - [0m13:07:31  Cleaned /opt/***/dbt_project/dbt_packages/*
[2025-10-25T15:07:31.005+0200] {subprocess.py:93} INFO - [0m13:07:31  Finished cleaning all paths.
[2025-10-25T15:07:35.718+0200] {subprocess.py:93} INFO - [0m13:07:35  Running with dbt=1.8.3
[2025-10-25T15:07:36.328+0200] {subprocess.py:93} INFO - [0m13:07:36  Registered adapter: postgres=1.8.2
[2025-10-25T15:07:36.517+0200] {subprocess.py:93} INFO - [0m13:07:36  Unable to do partial parsing because saved manifest not found. Starting full parse.
[2025-10-25T15:07:38.834+0200] {subprocess.py:93} INFO - [0m13:07:38  [[33mWARNING[0m]: Deprecated functionality
[2025-10-25T15:07:38.835+0200] {subprocess.py:93} INFO - The `tests` config has been renamed to `data_tests`. Please see
[2025-10-25T15:07:38.835+0200] {subprocess.py:93} INFO - https://docs.getdbt.com/docs/build/data-tests#new-data_tests-syntax for more
[2025-10-25T15:07:38.835+0200] {subprocess.py:93} INFO - information.
[2025-10-25T15:07:39.728+0200] {subprocess.py:93} INFO - [0m13:07:39  [[33mWARNING[0m]: Configuration paths exist in your dbt_project.yml file which do not apply to any resources.
[2025-10-25T15:07:39.729+0200] {subprocess.py:93} INFO - There are 1 unused configuration paths:
[2025-10-25T15:07:39.729+0200] {subprocess.py:93} INFO - - models.intermediters
[2025-10-25T15:07:40.216+0200] {subprocess.py:93} INFO - [0m13:07:40  Found 3 models, 6 data tests, 3 sources, 428 macros
[2025-10-25T15:07:40.223+0200] {subprocess.py:93} INFO - [0m13:07:40
[2025-10-25T15:07:40.524+0200] {subprocess.py:93} INFO - [0m13:07:40  Concurrency: 4 threads (target='dev')
[2025-10-25T15:07:40.525+0200] {subprocess.py:93} INFO - [0m13:07:40
[2025-10-25T15:07:40.561+0200] {subprocess.py:93} INFO - [0m13:07:40  1 of 3 START sql incremental model analytics.int_performance_station_hour ...... [RUN]
[2025-10-25T15:07:40.564+0200] {subprocess.py:93} INFO - [0m13:07:40  2 of 3 START sql incremental model analytics.int_quality_station_hour .......... [RUN]
[2025-10-25T15:07:40.628+0200] {subprocess.py:93} INFO - [0m13:07:40  [31mUnhandled error while executing [0m
[2025-10-25T15:07:40.629+0200] {subprocess.py:93} INFO - [Errno 13] Permission denied: '/opt/***/dbt_project/target/compiled/smt_project/models/intermediate/int_performance_station_hour.sql'
[2025-10-25T15:07:40.631+0200] {subprocess.py:93} INFO - [0m13:07:40  [31mUnhandled error while executing [0m
[2025-10-25T15:07:40.632+0200] {subprocess.py:93} INFO - [Errno 13] Permission denied: '/opt/***/dbt_project/target/compiled/smt_project/models/intermediate/int_quality_station_hour.sql'
[2025-10-25T15:07:40.647+0200] {subprocess.py:93} INFO - [0m13:07:40  2 of 3 ERROR creating sql incremental model analytics.int_quality_station_hour . [[31mERROR[0m in 0.08s]
[2025-10-25T15:07:40.661+0200] {subprocess.py:93} INFO - [0m13:07:40  1 of 3 ERROR creating sql incremental model analytics.int_performance_station_hour  [[31mERROR[0m in 0.09s]
[2025-10-25T15:07:40.667+0200] {subprocess.py:93} INFO - [0m13:07:40  3 of 3 SKIP relation analytics.int_quality_linewise_datehour ................... [[33mSKIP[0m]
[2025-10-25T15:07:40.702+0200] {subprocess.py:93} INFO - [0m13:07:40
[2025-10-25T15:07:40.703+0200] {subprocess.py:93} INFO - [0m13:07:40  Finished running 3 incremental models in 0 hours 0 minutes and 0.48 seconds (0.48s).
[2025-10-25T15:07:40.781+0200] {subprocess.py:93} INFO - [0m13:07:40
[2025-10-25T15:07:40.782+0200] {subprocess.py:93} INFO - [0m13:07:40  [31mCompleted with 2 errors and 0 warnings:[0m
[2025-10-25T15:07:40.783+0200] {subprocess.py:93} INFO - [0m13:07:40
[2025-10-25T15:07:40.784+0200] {subprocess.py:93} INFO - [0m13:07:40    [Errno 13] Permission denied: '/opt/***/dbt_project/target/compiled/smt_project/models/intermediate/int_quality_station_hour.sql'
[2025-10-25T15:07:40.785+0200] {subprocess.py:93} INFO - [0m13:07:40
[2025-10-25T15:07:40.786+0200] {subprocess.py:93} INFO - [0m13:07:40    [Errno 13] Permission denied: '/opt/***/dbt_project/target/compiled/smt_project/models/intermediate/int_performance_station_hour.sql'
[2025-10-25T15:07:40.787+0200] {subprocess.py:93} INFO - [0m13:07:40
[2025-10-25T15:07:40.788+0200] {subprocess.py:93} INFO - [0m13:07:40  Done. PASS=0 WARN=0 ERROR=2 SKIP=1 TOTAL=3
[2025-10-25T15:07:41.294+0200] {subprocess.py:97} INFO - Command exited with return code 1
[2025-10-25T15:07:41.324+0200] {taskinstance.py:3310} ERROR - Task failed with exception
Traceback (most recent call last):
  File "/home/airflow/.local/lib/python3.12/site-packages/airflow/models/taskinstance.py", line 767, in _execute_task
    result = _execute_callable(context=context, **execute_callable_kwargs)
             ^^^^^^^^^^^^^^^^^^^^^^^^^^^^^^^^^^^^^^^^^^^^^^^^^^^^^^^^^^^^^
  File "/home/airflow/.local/lib/python3.12/site-packages/airflow/models/taskinstance.py", line 733, in _execute_callable
    return ExecutionCallableRunner(
           ^^^^^^^^^^^^^^^^^^^^^^^^
  File "/home/airflow/.local/lib/python3.12/site-packages/airflow/utils/operator_helpers.py", line 252, in run
    return self.func(*args, **kwargs)
           ^^^^^^^^^^^^^^^^^^^^^^^^^^
  File "/home/airflow/.local/lib/python3.12/site-packages/airflow/models/baseoperator.py", line 406, in wrapper
    return func(self, *args, **kwargs)
           ^^^^^^^^^^^^^^^^^^^^^^^^^^^
  File "/home/airflow/.local/lib/python3.12/site-packages/airflow/operators/bash.py", line 249, in execute
    raise AirflowException(
airflow.exceptions.AirflowException: Bash command failed. The command returned a non-zero exit code 1.
[2025-10-25T15:07:41.348+0200] {taskinstance.py:1225} INFO - Marking task as UP_FOR_RETRY. dag_id=dbt_hourly_refresh, task_id=run_dbt_models, run_id=scheduled__2025-10-25T12:00:00+00:00, execution_date=20251025T120000, start_date=20251025T130726, end_date=20251025T130741
[2025-10-25T15:07:41.390+0200] {taskinstance.py:340} INFO - ::group::Post task execution logs
[2025-10-25T15:07:41.391+0200] {standard_task_runner.py:124} ERROR - Failed to execute job 46 for task run_dbt_models (Bash command failed. The command returned a non-zero exit code 1.; 260)
Traceback (most recent call last):
  File "/home/airflow/.local/lib/python3.12/site-packages/airflow/task/task_runner/standard_task_runner.py", line 117, in _start_by_fork
    ret = args.func(args, dag=self.dag)
          ^^^^^^^^^^^^^^^^^^^^^^^^^^^^^
  File "/home/airflow/.local/lib/python3.12/site-packages/airflow/cli/cli_config.py", line 49, in command
    return func(*args, **kwargs)
           ^^^^^^^^^^^^^^^^^^^^^
  File "/home/airflow/.local/lib/python3.12/site-packages/airflow/utils/cli.py", line 115, in wrapper
    return f(*args, **kwargs)
           ^^^^^^^^^^^^^^^^^^
  File "/home/airflow/.local/lib/python3.12/site-packages/airflow/cli/commands/task_command.py", line 483, in task_run
    task_return_code = _run_task_by_selected_method(args, _dag, ti)
                       ^^^^^^^^^^^^^^^^^^^^^^^^^^^^^^^^^^^^^^^^^^^^
  File "/home/airflow/.local/lib/python3.12/site-packages/airflow/cli/commands/task_command.py", line 256, in _run_task_by_selected_method
    return _run_raw_task(args, ti)
           ^^^^^^^^^^^^^^^^^^^^^^^
  File "/home/airflow/.local/lib/python3.12/site-packages/airflow/cli/commands/task_command.py", line 341, in _run_raw_task
    return ti._run_raw_task(
           ^^^^^^^^^^^^^^^^^
  File "/home/airflow/.local/lib/python3.12/site-packages/airflow/utils/session.py", line 97, in wrapper
    return func(*args, session=session, **kwargs)
           ^^^^^^^^^^^^^^^^^^^^^^^^^^^^^^^^^^^^^^
  File "/home/airflow/.local/lib/python3.12/site-packages/airflow/models/taskinstance.py", line 3004, in _run_raw_task
    return _run_raw_task(
           ^^^^^^^^^^^^^^
  File "/home/airflow/.local/lib/python3.12/site-packages/airflow/models/taskinstance.py", line 273, in _run_raw_task
    TaskInstance._execute_task_with_callbacks(
  File "/home/airflow/.local/lib/python3.12/site-packages/airflow/models/taskinstance.py", line 3158, in _execute_task_with_callbacks
    result = self._execute_task(context, task_orig)
             ^^^^^^^^^^^^^^^^^^^^^^^^^^^^^^^^^^^^^^
  File "/home/airflow/.local/lib/python3.12/site-packages/airflow/models/taskinstance.py", line 3182, in _execute_task
    return _execute_task(self, context, task_orig)
           ^^^^^^^^^^^^^^^^^^^^^^^^^^^^^^^^^^^^^^^
  File "/home/airflow/.local/lib/python3.12/site-packages/airflow/models/taskinstance.py", line 767, in _execute_task
    result = _execute_callable(context=context, **execute_callable_kwargs)
             ^^^^^^^^^^^^^^^^^^^^^^^^^^^^^^^^^^^^^^^^^^^^^^^^^^^^^^^^^^^^^
  File "/home/airflow/.local/lib/python3.12/site-packages/airflow/models/taskinstance.py", line 733, in _execute_callable
    return ExecutionCallableRunner(
           ^^^^^^^^^^^^^^^^^^^^^^^^
  File "/home/airflow/.local/lib/python3.12/site-packages/airflow/utils/operator_helpers.py", line 252, in run
    return self.func(*args, **kwargs)
           ^^^^^^^^^^^^^^^^^^^^^^^^^^
  File "/home/airflow/.local/lib/python3.12/site-packages/airflow/models/baseoperator.py", line 406, in wrapper
    return func(self, *args, **kwargs)
           ^^^^^^^^^^^^^^^^^^^^^^^^^^^
  File "/home/airflow/.local/lib/python3.12/site-packages/airflow/operators/bash.py", line 249, in execute
    raise AirflowException(
airflow.exceptions.AirflowException: Bash command failed. The command returned a non-zero exit code 1.
[2025-10-25T15:07:41.417+0200] {local_task_job_runner.py:266} INFO - Task exited with return code 1
[2025-10-25T15:07:41.450+0200] {taskinstance.py:3900} INFO - 0 downstream tasks scheduled from follow-on schedule check
[2025-10-25T15:07:41.453+0200] {local_task_job_runner.py:245} INFO - ::endgroup::
