[2025-10-24T00:37:49.916+0200] {local_task_job_runner.py:123} INFO - ::group::Pre task execution logs
[2025-10-24T00:37:49.955+0200] {taskinstance.py:2612} INFO - Dependencies all met for dep_context=non-requeueable deps ti=<TaskInstance: dbt_hourly_refresh.run_dbt_models manual__2025-10-23T22:37:48.587107+00:00 [queued]>
[2025-10-24T00:37:49.972+0200] {taskinstance.py:2612} INFO - Dependencies all met for dep_context=requeueable deps ti=<TaskInstance: dbt_hourly_refresh.run_dbt_models manual__2025-10-23T22:37:48.587107+00:00 [queued]>
[2025-10-24T00:37:49.972+0200] {taskinstance.py:2865} INFO - Starting attempt 1 of 2
[2025-10-24T00:37:49.995+0200] {taskinstance.py:2888} INFO - Executing <Task(BashOperator): run_dbt_models> on 2025-10-23 22:37:48.587107+00:00
[2025-10-24T00:37:50.014+0200] {standard_task_runner.py:104} INFO - Running: ['***', 'tasks', 'run', 'dbt_hourly_refresh', 'run_dbt_models', 'manual__2025-10-23T22:37:48.587107+00:00', '--job-id', '18', '--raw', '--subdir', 'DAGS_FOLDER/dbt_hourly_refresh_dag.py', '--cfg-path', '/tmp/tmpvgd123g7']
[2025-10-24T00:37:50.022+0200] {standard_task_runner.py:105} INFO - Job 18: Subtask run_dbt_models
[2025-10-24T00:37:50.023+0200] {logging_mixin.py:190} WARNING - /home/***/.local/lib/python3.12/site-packages/***/task/task_runner/standard_task_runner.py:70 DeprecationWarning: This process (pid=651) is multi-threaded, use of fork() may lead to deadlocks in the child.
[2025-10-24T00:37:50.024+0200] {standard_task_runner.py:72} INFO - Started process 652 to run task
[2025-10-24T00:37:50.152+0200] {task_command.py:467} INFO - Running <TaskInstance: dbt_hourly_refresh.run_dbt_models manual__2025-10-23T22:37:48.587107+00:00 [running]> on host 0552639bb6f4
[2025-10-24T00:37:50.435+0200] {taskinstance.py:3131} INFO - Exporting env vars: AIRFLOW_CTX_DAG_OWNER='Aliostadi' AIRFLOW_CTX_DAG_ID='dbt_hourly_refresh' AIRFLOW_CTX_TASK_ID='run_dbt_models' AIRFLOW_CTX_EXECUTION_DATE='2025-10-23T22:37:48.587107+00:00' AIRFLOW_CTX_TRY_NUMBER='1' AIRFLOW_CTX_DAG_RUN_ID='manual__2025-10-23T22:37:48.587107+00:00'
[2025-10-24T00:37:50.437+0200] {taskinstance.py:731} INFO - ::endgroup::
[2025-10-24T00:37:50.517+0200] {subprocess.py:63} INFO - Tmp dir root location: /tmp
[2025-10-24T00:37:50.520+0200] {subprocess.py:75} INFO - Running command: ['/usr/bin/bash', '-c', 'cd /opt/***/dbt_project && dbt run']
[2025-10-24T00:37:50.543+0200] {subprocess.py:86} INFO - Output:
[2025-10-24T00:37:55.475+0200] {subprocess.py:93} INFO - [0m22:37:55  Encountered an error:
[2025-10-24T00:37:55.478+0200] {subprocess.py:93} INFO - [Errno 13] Permission denied: '/opt/***/dbt_project/logs/dbt.log'
[2025-10-24T00:37:55.489+0200] {subprocess.py:93} INFO - [0m22:37:55  Traceback (most recent call last):
[2025-10-24T00:37:55.490+0200] {subprocess.py:93} INFO -   File "/home/***/.local/lib/python3.12/site-packages/dbt/cli/requires.py", line 138, in wrapper
[2025-10-24T00:37:55.490+0200] {subprocess.py:93} INFO -     result, success = func(*args, **kwargs)
[2025-10-24T00:37:55.491+0200] {subprocess.py:93} INFO -                       ^^^^^^^^^^^^^^^^^^^^^
[2025-10-24T00:37:55.491+0200] {subprocess.py:93} INFO -   File "/home/***/.local/lib/python3.12/site-packages/dbt/cli/requires.py", line 77, in wrapper
[2025-10-24T00:37:55.492+0200] {subprocess.py:93} INFO -     setup_event_logger(flags=flags, callbacks=callbacks)
[2025-10-24T00:37:55.492+0200] {subprocess.py:93} INFO -   File "/home/***/.local/lib/python3.12/site-packages/dbt/events/logging.py", line 99, in setup_event_logger
[2025-10-24T00:37:55.493+0200] {subprocess.py:93} INFO -     add_logger_to_manager(
[2025-10-24T00:37:55.493+0200] {subprocess.py:93} INFO -   File "/home/***/.local/lib/python3.12/site-packages/dbt_common/events/event_manager_client.py", line 17, in add_logger_to_manager
[2025-10-24T00:37:55.494+0200] {subprocess.py:93} INFO -     _EVENT_MANAGER.add_logger(logger)
[2025-10-24T00:37:55.494+0200] {subprocess.py:93} INFO -   File "/home/***/.local/lib/python3.12/site-packages/dbt_common/events/event_manager.py", line 36, in add_logger
[2025-10-24T00:37:55.494+0200] {subprocess.py:93} INFO -     _JsonLogger(config) if config.line_format == LineFormat.Json else _TextLogger(config)
[2025-10-24T00:37:55.495+0200] {subprocess.py:93} INFO -                                                                       ^^^^^^^^^^^^^^^^^^^
[2025-10-24T00:37:55.495+0200] {subprocess.py:93} INFO -   File "/home/***/.local/lib/python3.12/site-packages/dbt_common/events/logger.py", line 147, in __init__
[2025-10-24T00:37:55.495+0200] {subprocess.py:93} INFO -     super().__init__(config)
[2025-10-24T00:37:55.496+0200] {subprocess.py:93} INFO -   File "/home/***/.local/lib/python3.12/site-packages/dbt_common/events/logger.py", line 107, in __init__
[2025-10-24T00:37:55.496+0200] {subprocess.py:93} INFO -     file_handler = RotatingFileHandler(
[2025-10-24T00:37:55.496+0200] {subprocess.py:93} INFO -                    ^^^^^^^^^^^^^^^^^^^^
[2025-10-24T00:37:55.497+0200] {subprocess.py:93} INFO -   File "/usr/local/lib/python3.12/logging/handlers.py", line 155, in __init__
[2025-10-24T00:37:55.497+0200] {subprocess.py:93} INFO -     BaseRotatingHandler.__init__(self, filename, mode, encoding=encoding,
[2025-10-24T00:37:55.498+0200] {subprocess.py:93} INFO -   File "/usr/local/lib/python3.12/logging/handlers.py", line 58, in __init__
[2025-10-24T00:37:55.498+0200] {subprocess.py:93} INFO -     logging.FileHandler.__init__(self, filename, mode=mode,
[2025-10-24T00:37:55.499+0200] {subprocess.py:93} INFO -   File "/usr/local/lib/python3.12/logging/__init__.py", line 1231, in __init__
[2025-10-24T00:37:55.499+0200] {subprocess.py:93} INFO -     StreamHandler.__init__(self, self._open())
[2025-10-24T00:37:55.500+0200] {subprocess.py:93} INFO -                                  ^^^^^^^^^^^^
[2025-10-24T00:37:55.500+0200] {subprocess.py:93} INFO -   File "/usr/local/lib/python3.12/logging/__init__.py", line 1263, in _open
[2025-10-24T00:37:55.500+0200] {subprocess.py:93} INFO -     return open_func(self.baseFilename, self.mode,
[2025-10-24T00:37:55.501+0200] {subprocess.py:93} INFO -            ^^^^^^^^^^^^^^^^^^^^^^^^^^^^^^^^^^^^^^^
[2025-10-24T00:37:55.501+0200] {subprocess.py:93} INFO - PermissionError: [Errno 13] Permission denied: '/opt/***/dbt_project/logs/dbt.log'
[2025-10-24T00:37:55.502+0200] {subprocess.py:93} INFO - 
[2025-10-24T00:37:55.864+0200] {subprocess.py:97} INFO - Command exited with return code 2
[2025-10-24T00:37:55.882+0200] {taskinstance.py:3310} ERROR - Task failed with exception
Traceback (most recent call last):
  File "/home/airflow/.local/lib/python3.12/site-packages/airflow/models/taskinstance.py", line 767, in _execute_task
    result = _execute_callable(context=context, **execute_callable_kwargs)
             ^^^^^^^^^^^^^^^^^^^^^^^^^^^^^^^^^^^^^^^^^^^^^^^^^^^^^^^^^^^^^
  File "/home/airflow/.local/lib/python3.12/site-packages/airflow/models/taskinstance.py", line 733, in _execute_callable
    return ExecutionCallableRunner(
           ^^^^^^^^^^^^^^^^^^^^^^^^
  File "/home/airflow/.local/lib/python3.12/site-packages/airflow/utils/operator_helpers.py", line 252, in run
    return self.func(*args, **kwargs)
           ^^^^^^^^^^^^^^^^^^^^^^^^^^
  File "/home/airflow/.local/lib/python3.12/site-packages/airflow/models/baseoperator.py", line 406, in wrapper
    return func(self, *args, **kwargs)
           ^^^^^^^^^^^^^^^^^^^^^^^^^^^
  File "/home/airflow/.local/lib/python3.12/site-packages/airflow/operators/bash.py", line 249, in execute
    raise AirflowException(
airflow.exceptions.AirflowException: Bash command failed. The command returned a non-zero exit code 2.
[2025-10-24T00:37:55.894+0200] {taskinstance.py:1225} INFO - Marking task as UP_FOR_RETRY. dag_id=dbt_hourly_refresh, task_id=run_dbt_models, run_id=manual__2025-10-23T22:37:48.587107+00:00, execution_date=20251023T223748, start_date=20251023T223749, end_date=20251023T223755
[2025-10-24T00:37:55.917+0200] {taskinstance.py:340} INFO - ::group::Post task execution logs
[2025-10-24T00:37:55.918+0200] {standard_task_runner.py:124} ERROR - Failed to execute job 18 for task run_dbt_models (Bash command failed. The command returned a non-zero exit code 2.; 652)
Traceback (most recent call last):
  File "/home/airflow/.local/lib/python3.12/site-packages/airflow/task/task_runner/standard_task_runner.py", line 117, in _start_by_fork
    ret = args.func(args, dag=self.dag)
          ^^^^^^^^^^^^^^^^^^^^^^^^^^^^^
  File "/home/airflow/.local/lib/python3.12/site-packages/airflow/cli/cli_config.py", line 49, in command
    return func(*args, **kwargs)
           ^^^^^^^^^^^^^^^^^^^^^
  File "/home/airflow/.local/lib/python3.12/site-packages/airflow/utils/cli.py", line 115, in wrapper
    return f(*args, **kwargs)
           ^^^^^^^^^^^^^^^^^^
  File "/home/airflow/.local/lib/python3.12/site-packages/airflow/cli/commands/task_command.py", line 483, in task_run
    task_return_code = _run_task_by_selected_method(args, _dag, ti)
                       ^^^^^^^^^^^^^^^^^^^^^^^^^^^^^^^^^^^^^^^^^^^^
  File "/home/airflow/.local/lib/python3.12/site-packages/airflow/cli/commands/task_command.py", line 256, in _run_task_by_selected_method
    return _run_raw_task(args, ti)
           ^^^^^^^^^^^^^^^^^^^^^^^
  File "/home/airflow/.local/lib/python3.12/site-packages/airflow/cli/commands/task_command.py", line 341, in _run_raw_task
    return ti._run_raw_task(
           ^^^^^^^^^^^^^^^^^
  File "/home/airflow/.local/lib/python3.12/site-packages/airflow/utils/session.py", line 97, in wrapper
    return func(*args, session=session, **kwargs)
           ^^^^^^^^^^^^^^^^^^^^^^^^^^^^^^^^^^^^^^
  File "/home/airflow/.local/lib/python3.12/site-packages/airflow/models/taskinstance.py", line 3004, in _run_raw_task
    return _run_raw_task(
           ^^^^^^^^^^^^^^
  File "/home/airflow/.local/lib/python3.12/site-packages/airflow/models/taskinstance.py", line 273, in _run_raw_task
    TaskInstance._execute_task_with_callbacks(
  File "/home/airflow/.local/lib/python3.12/site-packages/airflow/models/taskinstance.py", line 3158, in _execute_task_with_callbacks
    result = self._execute_task(context, task_orig)
             ^^^^^^^^^^^^^^^^^^^^^^^^^^^^^^^^^^^^^^
  File "/home/airflow/.local/lib/python3.12/site-packages/airflow/models/taskinstance.py", line 3182, in _execute_task
    return _execute_task(self, context, task_orig)
           ^^^^^^^^^^^^^^^^^^^^^^^^^^^^^^^^^^^^^^^
  File "/home/airflow/.local/lib/python3.12/site-packages/airflow/models/taskinstance.py", line 767, in _execute_task
    result = _execute_callable(context=context, **execute_callable_kwargs)
             ^^^^^^^^^^^^^^^^^^^^^^^^^^^^^^^^^^^^^^^^^^^^^^^^^^^^^^^^^^^^^
  File "/home/airflow/.local/lib/python3.12/site-packages/airflow/models/taskinstance.py", line 733, in _execute_callable
    return ExecutionCallableRunner(
           ^^^^^^^^^^^^^^^^^^^^^^^^
  File "/home/airflow/.local/lib/python3.12/site-packages/airflow/utils/operator_helpers.py", line 252, in run
    return self.func(*args, **kwargs)
           ^^^^^^^^^^^^^^^^^^^^^^^^^^
  File "/home/airflow/.local/lib/python3.12/site-packages/airflow/models/baseoperator.py", line 406, in wrapper
    return func(self, *args, **kwargs)
           ^^^^^^^^^^^^^^^^^^^^^^^^^^^
  File "/home/airflow/.local/lib/python3.12/site-packages/airflow/operators/bash.py", line 249, in execute
    raise AirflowException(
airflow.exceptions.AirflowException: Bash command failed. The command returned a non-zero exit code 2.
[2025-10-24T00:37:55.938+0200] {local_task_job_runner.py:266} INFO - Task exited with return code 1
[2025-10-24T00:37:55.958+0200] {taskinstance.py:3900} INFO - 0 downstream tasks scheduled from follow-on schedule check
[2025-10-24T00:37:55.960+0200] {local_task_job_runner.py:245} INFO - ::endgroup::
