[2025-10-24T01:00:00.702+0200] {local_task_job_runner.py:123} INFO - ::group::Pre task execution logs
[2025-10-24T01:00:00.766+0200] {taskinstance.py:2612} INFO - Dependencies all met for dep_context=non-requeueable deps ti=<TaskInstance: dbt_hourly_refresh.run_dbt_models scheduled__2025-10-23T22:00:00+00:00 [queued]>
[2025-10-24T01:00:00.787+0200] {taskinstance.py:2612} INFO - Dependencies all met for dep_context=requeueable deps ti=<TaskInstance: dbt_hourly_refresh.run_dbt_models scheduled__2025-10-23T22:00:00+00:00 [queued]>
[2025-10-24T01:00:00.788+0200] {taskinstance.py:2865} INFO - Starting attempt 1 of 2
[2025-10-24T01:00:00.813+0200] {taskinstance.py:2888} INFO - Executing <Task(BashOperator): run_dbt_models> on 2025-10-23 22:00:00+00:00
[2025-10-24T01:00:00.829+0200] {standard_task_runner.py:104} INFO - Running: ['***', 'tasks', 'run', 'dbt_hourly_refresh', 'run_dbt_models', 'scheduled__2025-10-23T22:00:00+00:00', '--job-id', '26', '--raw', '--subdir', 'DAGS_FOLDER/dbt_hourly_refresh_dag.py', '--cfg-path', '/tmp/tmp_xkq5wtn']
[2025-10-24T01:00:00.836+0200] {standard_task_runner.py:105} INFO - Job 26: Subtask run_dbt_models
[2025-10-24T01:00:00.837+0200] {logging_mixin.py:190} WARNING - /home/***/.local/lib/python3.12/site-packages/***/task/task_runner/standard_task_runner.py:70 DeprecationWarning: This process (pid=307) is multi-threaded, use of fork() may lead to deadlocks in the child.
[2025-10-24T01:00:00.838+0200] {standard_task_runner.py:72} INFO - Started process 308 to run task
[2025-10-24T01:00:00.937+0200] {task_command.py:467} INFO - Running <TaskInstance: dbt_hourly_refresh.run_dbt_models scheduled__2025-10-23T22:00:00+00:00 [running]> on host e12330ab4681
[2025-10-24T01:00:01.051+0200] {taskinstance.py:3131} INFO - Exporting env vars: AIRFLOW_CTX_DAG_OWNER='Aliostadi' AIRFLOW_CTX_DAG_ID='dbt_hourly_refresh' AIRFLOW_CTX_TASK_ID='run_dbt_models' AIRFLOW_CTX_EXECUTION_DATE='2025-10-23T22:00:00+00:00' AIRFLOW_CTX_TRY_NUMBER='1' AIRFLOW_CTX_DAG_RUN_ID='scheduled__2025-10-23T22:00:00+00:00'
[2025-10-24T01:00:01.052+0200] {taskinstance.py:731} INFO - ::endgroup::
[2025-10-24T01:00:01.102+0200] {subprocess.py:63} INFO - Tmp dir root location: /tmp
[2025-10-24T01:00:01.103+0200] {subprocess.py:75} INFO - Running command: ['/usr/bin/bash', '-c', 'cd /opt/***/dbt_project && dbt run']
[2025-10-24T01:00:01.123+0200] {subprocess.py:86} INFO - Output:
[2025-10-24T01:00:07.809+0200] {subprocess.py:93} INFO - [0m23:00:07  Running with dbt=1.8.5
[2025-10-24T01:00:08.934+0200] {subprocess.py:93} INFO - [0m23:00:08  Registered adapter: postgres=1.8.2
[2025-10-24T01:00:09.492+0200] {subprocess.py:93} INFO - [0m23:00:09  [[33mWARNING[0m]: Configuration paths exist in your dbt_project.yml file which do not apply to any resources.
[2025-10-24T01:00:09.492+0200] {subprocess.py:93} INFO - There are 1 unused configuration paths:
[2025-10-24T01:00:09.493+0200] {subprocess.py:93} INFO - - models.intermediters
[2025-10-24T01:00:09.936+0200] {subprocess.py:93} INFO - [0m23:00:09  Found 3 models, 6 data tests, 3 sources, 428 macros
[2025-10-24T01:00:09.942+0200] {subprocess.py:93} INFO - [0m23:00:09
[2025-10-24T01:00:10.404+0200] {subprocess.py:93} INFO - [0m23:00:10  Concurrency: 4 threads (target='dev')
[2025-10-24T01:00:10.405+0200] {subprocess.py:93} INFO - [0m23:00:10
[2025-10-24T01:00:10.448+0200] {subprocess.py:93} INFO - [0m23:00:10  1 of 3 START sql incremental model analytics.int_performance_station_hour ...... [RUN]
[2025-10-24T01:00:10.451+0200] {subprocess.py:93} INFO - [0m23:00:10  2 of 3 START sql incremental model analytics.int_quality_station_hour .......... [RUN]
[2025-10-24T01:00:11.295+0200] {subprocess.py:93} INFO - [0m23:00:11  2 of 3 ERROR creating sql incremental model analytics.int_quality_station_hour . [[31mERROR[0m in 0.83s]
[2025-10-24T01:00:11.353+0200] {subprocess.py:93} INFO - [0m23:00:11  3 of 3 SKIP relation analytics.int_quality_linewise_datehour ................... [[33mSKIP[0m]
[2025-10-24T01:00:11.758+0200] {subprocess.py:93} INFO - [0m23:00:11  1 of 3 OK created sql incremental model analytics.int_performance_station_hour . [[32mINSERT 0 8[0m in 1.30s]
[2025-10-24T01:00:11.822+0200] {subprocess.py:93} INFO - [0m23:00:11
[2025-10-24T01:00:11.825+0200] {subprocess.py:93} INFO - [0m23:00:11  Finished running 3 incremental models in 0 hours 0 minutes and 1.88 seconds (1.88s).
[2025-10-24T01:00:11.941+0200] {subprocess.py:93} INFO - [0m23:00:11
[2025-10-24T01:00:11.942+0200] {subprocess.py:93} INFO - [0m23:00:11  [31mCompleted with 1 error and 0 warnings:[0m
[2025-10-24T01:00:11.943+0200] {subprocess.py:93} INFO - [0m23:00:11
[2025-10-24T01:00:11.945+0200] {subprocess.py:93} INFO - [0m23:00:11    Database Error in model int_quality_station_hour (models/intermediate/int_quality_station_hour.sql)
[2025-10-24T01:00:11.947+0200] {subprocess.py:93} INFO -   aggregate functions are not allowed in WHERE
[2025-10-24T01:00:11.947+0200] {subprocess.py:93} INFO -   LINE 31:         WHERE date_created > (SELECT MAX(date_created) FROM ...
[2025-10-24T01:00:11.948+0200] {subprocess.py:93} INFO -                                                 ^
[2025-10-24T01:00:11.949+0200] {subprocess.py:93} INFO - [0m23:00:11
[2025-10-24T01:00:11.950+0200] {subprocess.py:93} INFO - [0m23:00:11  Done. PASS=1 WARN=0 ERROR=1 SKIP=1 TOTAL=3
[2025-10-24T01:00:12.733+0200] {subprocess.py:97} INFO - Command exited with return code 1
[2025-10-24T01:00:12.867+0200] {taskinstance.py:3310} ERROR - Task failed with exception
Traceback (most recent call last):
  File "/home/airflow/.local/lib/python3.12/site-packages/airflow/models/taskinstance.py", line 767, in _execute_task
    result = _execute_callable(context=context, **execute_callable_kwargs)
             ^^^^^^^^^^^^^^^^^^^^^^^^^^^^^^^^^^^^^^^^^^^^^^^^^^^^^^^^^^^^^
  File "/home/airflow/.local/lib/python3.12/site-packages/airflow/models/taskinstance.py", line 733, in _execute_callable
    return ExecutionCallableRunner(
           ^^^^^^^^^^^^^^^^^^^^^^^^
  File "/home/airflow/.local/lib/python3.12/site-packages/airflow/utils/operator_helpers.py", line 252, in run
    return self.func(*args, **kwargs)
           ^^^^^^^^^^^^^^^^^^^^^^^^^^
  File "/home/airflow/.local/lib/python3.12/site-packages/airflow/models/baseoperator.py", line 406, in wrapper
    return func(self, *args, **kwargs)
           ^^^^^^^^^^^^^^^^^^^^^^^^^^^
  File "/home/airflow/.local/lib/python3.12/site-packages/airflow/operators/bash.py", line 249, in execute
    raise AirflowException(
airflow.exceptions.AirflowException: Bash command failed. The command returned a non-zero exit code 1.
[2025-10-24T01:00:12.908+0200] {taskinstance.py:1225} INFO - Marking task as UP_FOR_RETRY. dag_id=dbt_hourly_refresh, task_id=run_dbt_models, run_id=scheduled__2025-10-23T22:00:00+00:00, execution_date=20251023T220000, start_date=20251023T230000, end_date=20251023T230012
[2025-10-24T01:00:12.960+0200] {taskinstance.py:340} INFO - ::group::Post task execution logs
[2025-10-24T01:00:12.961+0200] {standard_task_runner.py:124} ERROR - Failed to execute job 26 for task run_dbt_models (Bash command failed. The command returned a non-zero exit code 1.; 308)
Traceback (most recent call last):
  File "/home/airflow/.local/lib/python3.12/site-packages/airflow/task/task_runner/standard_task_runner.py", line 117, in _start_by_fork
    ret = args.func(args, dag=self.dag)
          ^^^^^^^^^^^^^^^^^^^^^^^^^^^^^
  File "/home/airflow/.local/lib/python3.12/site-packages/airflow/cli/cli_config.py", line 49, in command
    return func(*args, **kwargs)
           ^^^^^^^^^^^^^^^^^^^^^
  File "/home/airflow/.local/lib/python3.12/site-packages/airflow/utils/cli.py", line 115, in wrapper
    return f(*args, **kwargs)
           ^^^^^^^^^^^^^^^^^^
  File "/home/airflow/.local/lib/python3.12/site-packages/airflow/cli/commands/task_command.py", line 483, in task_run
    task_return_code = _run_task_by_selected_method(args, _dag, ti)
                       ^^^^^^^^^^^^^^^^^^^^^^^^^^^^^^^^^^^^^^^^^^^^
  File "/home/airflow/.local/lib/python3.12/site-packages/airflow/cli/commands/task_command.py", line 256, in _run_task_by_selected_method
    return _run_raw_task(args, ti)
           ^^^^^^^^^^^^^^^^^^^^^^^
  File "/home/airflow/.local/lib/python3.12/site-packages/airflow/cli/commands/task_command.py", line 341, in _run_raw_task
    return ti._run_raw_task(
           ^^^^^^^^^^^^^^^^^
  File "/home/airflow/.local/lib/python3.12/site-packages/airflow/utils/session.py", line 97, in wrapper
    return func(*args, session=session, **kwargs)
           ^^^^^^^^^^^^^^^^^^^^^^^^^^^^^^^^^^^^^^
  File "/home/airflow/.local/lib/python3.12/site-packages/airflow/models/taskinstance.py", line 3004, in _run_raw_task
    return _run_raw_task(
           ^^^^^^^^^^^^^^
  File "/home/airflow/.local/lib/python3.12/site-packages/airflow/models/taskinstance.py", line 273, in _run_raw_task
    TaskInstance._execute_task_with_callbacks(
  File "/home/airflow/.local/lib/python3.12/site-packages/airflow/models/taskinstance.py", line 3158, in _execute_task_with_callbacks
    result = self._execute_task(context, task_orig)
             ^^^^^^^^^^^^^^^^^^^^^^^^^^^^^^^^^^^^^^
  File "/home/airflow/.local/lib/python3.12/site-packages/airflow/models/taskinstance.py", line 3182, in _execute_task
    return _execute_task(self, context, task_orig)
           ^^^^^^^^^^^^^^^^^^^^^^^^^^^^^^^^^^^^^^^
  File "/home/airflow/.local/lib/python3.12/site-packages/airflow/models/taskinstance.py", line 767, in _execute_task
    result = _execute_callable(context=context, **execute_callable_kwargs)
             ^^^^^^^^^^^^^^^^^^^^^^^^^^^^^^^^^^^^^^^^^^^^^^^^^^^^^^^^^^^^^
  File "/home/airflow/.local/lib/python3.12/site-packages/airflow/models/taskinstance.py", line 733, in _execute_callable
    return ExecutionCallableRunner(
           ^^^^^^^^^^^^^^^^^^^^^^^^
  File "/home/airflow/.local/lib/python3.12/site-packages/airflow/utils/operator_helpers.py", line 252, in run
    return self.func(*args, **kwargs)
           ^^^^^^^^^^^^^^^^^^^^^^^^^^
  File "/home/airflow/.local/lib/python3.12/site-packages/airflow/models/baseoperator.py", line 406, in wrapper
    return func(self, *args, **kwargs)
           ^^^^^^^^^^^^^^^^^^^^^^^^^^^
  File "/home/airflow/.local/lib/python3.12/site-packages/airflow/operators/bash.py", line 249, in execute
    raise AirflowException(
airflow.exceptions.AirflowException: Bash command failed. The command returned a non-zero exit code 1.
[2025-10-24T01:00:13.024+0200] {local_task_job_runner.py:266} INFO - Task exited with return code 1
[2025-10-24T01:00:13.063+0200] {taskinstance.py:3900} INFO - 0 downstream tasks scheduled from follow-on schedule check
[2025-10-24T01:00:13.066+0200] {local_task_job_runner.py:245} INFO - ::endgroup::
