[2025-10-25T13:51:39.670+0200] {local_task_job_runner.py:123} INFO - ::group::Pre task execution logs
[2025-10-25T13:51:39.718+0200] {taskinstance.py:2612} INFO - Dependencies all met for dep_context=non-requeueable deps ti=<TaskInstance: dbt_hourly_refresh.run_dbt_models manual__2025-10-23T23:31:31.257865+00:00 [queued]>
[2025-10-25T13:51:39.739+0200] {taskinstance.py:2612} INFO - Dependencies all met for dep_context=requeueable deps ti=<TaskInstance: dbt_hourly_refresh.run_dbt_models manual__2025-10-23T23:31:31.257865+00:00 [queued]>
[2025-10-25T13:51:39.740+0200] {taskinstance.py:2865} INFO - Starting attempt 3 of 2
[2025-10-25T13:51:39.781+0200] {taskinstance.py:2888} INFO - Executing <Task(BashOperator): run_dbt_models> on 2025-10-23 23:31:31.257865+00:00
[2025-10-25T13:51:39.803+0200] {standard_task_runner.py:104} INFO - Running: ['***', 'tasks', 'run', 'dbt_hourly_refresh', 'run_dbt_models', 'manual__2025-10-23T23:31:31.257865+00:00', '--job-id', '37', '--raw', '--subdir', 'DAGS_FOLDER/dbt_hourly_refresh_dag.py', '--cfg-path', '/tmp/tmp9gbimjmn']
[2025-10-25T13:51:39.812+0200] {standard_task_runner.py:105} INFO - Job 37: Subtask run_dbt_models
[2025-10-25T13:51:39.816+0200] {logging_mixin.py:190} WARNING - /home/***/.local/lib/python3.12/site-packages/***/task/task_runner/standard_task_runner.py:70 DeprecationWarning: This process (pid=257) is multi-threaded, use of fork() may lead to deadlocks in the child.
[2025-10-25T13:51:39.818+0200] {standard_task_runner.py:72} INFO - Started process 263 to run task
[2025-10-25T13:51:39.966+0200] {task_command.py:467} INFO - Running <TaskInstance: dbt_hourly_refresh.run_dbt_models manual__2025-10-23T23:31:31.257865+00:00 [running]> on host dae0b9df8402
[2025-10-25T13:51:40.261+0200] {taskinstance.py:3131} INFO - Exporting env vars: AIRFLOW_CTX_DAG_OWNER='Aliostadi' AIRFLOW_CTX_DAG_ID='dbt_hourly_refresh' AIRFLOW_CTX_TASK_ID='run_dbt_models' AIRFLOW_CTX_EXECUTION_DATE='2025-10-23T23:31:31.257865+00:00' AIRFLOW_CTX_TRY_NUMBER='3' AIRFLOW_CTX_DAG_RUN_ID='manual__2025-10-23T23:31:31.257865+00:00'
[2025-10-25T13:51:40.262+0200] {taskinstance.py:731} INFO - ::endgroup::
[2025-10-25T13:51:40.412+0200] {subprocess.py:63} INFO - Tmp dir root location: /tmp
[2025-10-25T13:51:40.415+0200] {subprocess.py:75} INFO - Running command: ['/usr/bin/bash', '-c', 'cd /opt/***/dbt_project && dbt clean && dbt run --full-refresh']
[2025-10-25T13:51:40.438+0200] {subprocess.py:86} INFO - Output:
[2025-10-25T13:51:48.193+0200] {subprocess.py:93} INFO - [0m11:51:48  Running with dbt=1.8.3
[2025-10-25T13:51:48.892+0200] {subprocess.py:93} INFO - [0m11:51:48  Checking /opt/***/dbt_project/dbt_packages/*
[2025-10-25T13:51:48.894+0200] {subprocess.py:93} INFO - [0m11:51:48  Cleaned /opt/***/dbt_project/dbt_packages/*
[2025-10-25T13:51:48.895+0200] {subprocess.py:93} INFO - [0m11:51:48  Checking /opt/***/dbt_project/target/*
[2025-10-25T13:51:48.906+0200] {subprocess.py:93} INFO - [0m11:51:48  Cleaned /opt/***/dbt_project/target/*
[2025-10-25T13:51:48.907+0200] {subprocess.py:93} INFO - [0m11:51:48  Finished cleaning all paths.
[2025-10-25T13:51:56.978+0200] {subprocess.py:93} INFO - [0m11:51:56  Running with dbt=1.8.3
[2025-10-25T13:51:58.268+0200] {subprocess.py:93} INFO - [0m11:51:58  Registered adapter: postgres=1.8.2
[2025-10-25T13:51:58.740+0200] {subprocess.py:93} INFO - [0m11:51:58  Unable to do partial parsing because saved manifest not found. Starting full parse.
[2025-10-25T13:52:02.197+0200] {subprocess.py:93} INFO - [0m11:52:02  [[33mWARNING[0m]: Deprecated functionality
[2025-10-25T13:52:02.198+0200] {subprocess.py:93} INFO - The `tests` config has been renamed to `data_tests`. Please see
[2025-10-25T13:52:02.198+0200] {subprocess.py:93} INFO - https://docs.getdbt.com/docs/build/data-tests#new-data_tests-syntax for more
[2025-10-25T13:52:02.199+0200] {subprocess.py:93} INFO - information.
[2025-10-25T13:52:02.943+0200] {subprocess.py:93} INFO - [0m11:52:02  [[33mWARNING[0m]: Configuration paths exist in your dbt_project.yml file which do not apply to any resources.
[2025-10-25T13:52:02.944+0200] {subprocess.py:93} INFO - There are 1 unused configuration paths:
[2025-10-25T13:52:02.945+0200] {subprocess.py:93} INFO - - models.intermediters
[2025-10-25T13:52:03.346+0200] {subprocess.py:93} INFO - [0m11:52:03  Found 3 models, 6 data tests, 3 sources, 428 macros
[2025-10-25T13:52:03.351+0200] {subprocess.py:93} INFO - [0m11:52:03
[2025-10-25T13:52:03.577+0200] {subprocess.py:93} INFO - [0m11:52:03  Concurrency: 4 threads (target='dev')
[2025-10-25T13:52:03.578+0200] {subprocess.py:93} INFO - [0m11:52:03
[2025-10-25T13:52:03.603+0200] {subprocess.py:93} INFO - [0m11:52:03  1 of 3 START sql incremental model analytics.int_performance_station_hour ...... [RUN]
[2025-10-25T13:52:03.606+0200] {subprocess.py:93} INFO - [0m11:52:03  2 of 3 START sql incremental model analytics.int_quality_station_hour .......... [RUN]
[2025-10-25T13:52:03.656+0200] {subprocess.py:93} INFO - [0m11:52:03  [31mUnhandled error while executing [0m
[2025-10-25T13:52:03.656+0200] {subprocess.py:93} INFO - [Errno 13] Permission denied: '/opt/***/dbt_project/target/compiled/smt_project/models/intermediate/int_performance_station_hour.sql'
[2025-10-25T13:52:03.661+0200] {subprocess.py:93} INFO - [0m11:52:03  [31mUnhandled error while executing [0m
[2025-10-25T13:52:03.661+0200] {subprocess.py:93} INFO - [Errno 13] Permission denied: '/opt/***/dbt_project/target/compiled/smt_project/models/intermediate/int_quality_station_hour.sql'
[2025-10-25T13:52:03.677+0200] {subprocess.py:93} INFO - [0m11:52:03  1 of 3 ERROR creating sql incremental model analytics.int_performance_station_hour  [[31mERROR[0m in 0.06s]
[2025-10-25T13:52:03.680+0200] {subprocess.py:93} INFO - [0m11:52:03  2 of 3 ERROR creating sql incremental model analytics.int_quality_station_hour . [[31mERROR[0m in 0.06s]
[2025-10-25T13:52:03.691+0200] {subprocess.py:93} INFO - [0m11:52:03  3 of 3 SKIP relation analytics.int_quality_linewise_datehour ................... [[33mSKIP[0m]
[2025-10-25T13:52:03.725+0200] {subprocess.py:93} INFO - [0m11:52:03
[2025-10-25T13:52:03.726+0200] {subprocess.py:93} INFO - [0m11:52:03  Finished running 3 incremental models in 0 hours 0 minutes and 0.37 seconds (0.37s).
[2025-10-25T13:52:03.802+0200] {subprocess.py:93} INFO - [0m11:52:03
[2025-10-25T13:52:03.803+0200] {subprocess.py:93} INFO - [0m11:52:03  [31mCompleted with 2 errors and 0 warnings:[0m
[2025-10-25T13:52:03.805+0200] {subprocess.py:93} INFO - [0m11:52:03
[2025-10-25T13:52:03.805+0200] {subprocess.py:93} INFO - [0m11:52:03    [Errno 13] Permission denied: '/opt/***/dbt_project/target/compiled/smt_project/models/intermediate/int_performance_station_hour.sql'
[2025-10-25T13:52:03.806+0200] {subprocess.py:93} INFO - [0m11:52:03
[2025-10-25T13:52:03.807+0200] {subprocess.py:93} INFO - [0m11:52:03    [Errno 13] Permission denied: '/opt/***/dbt_project/target/compiled/smt_project/models/intermediate/int_quality_station_hour.sql'
[2025-10-25T13:52:03.808+0200] {subprocess.py:93} INFO - [0m11:52:03
[2025-10-25T13:52:03.808+0200] {subprocess.py:93} INFO - [0m11:52:03  Done. PASS=0 WARN=0 ERROR=2 SKIP=1 TOTAL=3
[2025-10-25T13:52:04.358+0200] {subprocess.py:97} INFO - Command exited with return code 1
[2025-10-25T13:52:04.391+0200] {taskinstance.py:3310} ERROR - Task failed with exception
Traceback (most recent call last):
  File "/home/airflow/.local/lib/python3.12/site-packages/airflow/models/taskinstance.py", line 767, in _execute_task
    result = _execute_callable(context=context, **execute_callable_kwargs)
             ^^^^^^^^^^^^^^^^^^^^^^^^^^^^^^^^^^^^^^^^^^^^^^^^^^^^^^^^^^^^^
  File "/home/airflow/.local/lib/python3.12/site-packages/airflow/models/taskinstance.py", line 733, in _execute_callable
    return ExecutionCallableRunner(
           ^^^^^^^^^^^^^^^^^^^^^^^^
  File "/home/airflow/.local/lib/python3.12/site-packages/airflow/utils/operator_helpers.py", line 252, in run
    return self.func(*args, **kwargs)
           ^^^^^^^^^^^^^^^^^^^^^^^^^^
  File "/home/airflow/.local/lib/python3.12/site-packages/airflow/models/baseoperator.py", line 406, in wrapper
    return func(self, *args, **kwargs)
           ^^^^^^^^^^^^^^^^^^^^^^^^^^^
  File "/home/airflow/.local/lib/python3.12/site-packages/airflow/operators/bash.py", line 249, in execute
    raise AirflowException(
airflow.exceptions.AirflowException: Bash command failed. The command returned a non-zero exit code 1.
[2025-10-25T13:52:04.400+0200] {taskinstance.py:1225} INFO - Marking task as FAILED. dag_id=dbt_hourly_refresh, task_id=run_dbt_models, run_id=manual__2025-10-23T23:31:31.257865+00:00, execution_date=20251023T233131, start_date=20251025T115139, end_date=20251025T115204
[2025-10-25T13:52:04.432+0200] {taskinstance.py:340} INFO - ::group::Post task execution logs
[2025-10-25T13:52:04.434+0200] {standard_task_runner.py:124} ERROR - Failed to execute job 37 for task run_dbt_models (Bash command failed. The command returned a non-zero exit code 1.; 263)
Traceback (most recent call last):
  File "/home/airflow/.local/lib/python3.12/site-packages/airflow/task/task_runner/standard_task_runner.py", line 117, in _start_by_fork
    ret = args.func(args, dag=self.dag)
          ^^^^^^^^^^^^^^^^^^^^^^^^^^^^^
  File "/home/airflow/.local/lib/python3.12/site-packages/airflow/cli/cli_config.py", line 49, in command
    return func(*args, **kwargs)
           ^^^^^^^^^^^^^^^^^^^^^
  File "/home/airflow/.local/lib/python3.12/site-packages/airflow/utils/cli.py", line 115, in wrapper
    return f(*args, **kwargs)
           ^^^^^^^^^^^^^^^^^^
  File "/home/airflow/.local/lib/python3.12/site-packages/airflow/cli/commands/task_command.py", line 483, in task_run
    task_return_code = _run_task_by_selected_method(args, _dag, ti)
                       ^^^^^^^^^^^^^^^^^^^^^^^^^^^^^^^^^^^^^^^^^^^^
  File "/home/airflow/.local/lib/python3.12/site-packages/airflow/cli/commands/task_command.py", line 256, in _run_task_by_selected_method
    return _run_raw_task(args, ti)
           ^^^^^^^^^^^^^^^^^^^^^^^
  File "/home/airflow/.local/lib/python3.12/site-packages/airflow/cli/commands/task_command.py", line 341, in _run_raw_task
    return ti._run_raw_task(
           ^^^^^^^^^^^^^^^^^
  File "/home/airflow/.local/lib/python3.12/site-packages/airflow/utils/session.py", line 97, in wrapper
    return func(*args, session=session, **kwargs)
           ^^^^^^^^^^^^^^^^^^^^^^^^^^^^^^^^^^^^^^
  File "/home/airflow/.local/lib/python3.12/site-packages/airflow/models/taskinstance.py", line 3004, in _run_raw_task
    return _run_raw_task(
           ^^^^^^^^^^^^^^
  File "/home/airflow/.local/lib/python3.12/site-packages/airflow/models/taskinstance.py", line 273, in _run_raw_task
    TaskInstance._execute_task_with_callbacks(
  File "/home/airflow/.local/lib/python3.12/site-packages/airflow/models/taskinstance.py", line 3158, in _execute_task_with_callbacks
    result = self._execute_task(context, task_orig)
             ^^^^^^^^^^^^^^^^^^^^^^^^^^^^^^^^^^^^^^
  File "/home/airflow/.local/lib/python3.12/site-packages/airflow/models/taskinstance.py", line 3182, in _execute_task
    return _execute_task(self, context, task_orig)
           ^^^^^^^^^^^^^^^^^^^^^^^^^^^^^^^^^^^^^^^
  File "/home/airflow/.local/lib/python3.12/site-packages/airflow/models/taskinstance.py", line 767, in _execute_task
    result = _execute_callable(context=context, **execute_callable_kwargs)
             ^^^^^^^^^^^^^^^^^^^^^^^^^^^^^^^^^^^^^^^^^^^^^^^^^^^^^^^^^^^^^
  File "/home/airflow/.local/lib/python3.12/site-packages/airflow/models/taskinstance.py", line 733, in _execute_callable
    return ExecutionCallableRunner(
           ^^^^^^^^^^^^^^^^^^^^^^^^
  File "/home/airflow/.local/lib/python3.12/site-packages/airflow/utils/operator_helpers.py", line 252, in run
    return self.func(*args, **kwargs)
           ^^^^^^^^^^^^^^^^^^^^^^^^^^
  File "/home/airflow/.local/lib/python3.12/site-packages/airflow/models/baseoperator.py", line 406, in wrapper
    return func(self, *args, **kwargs)
           ^^^^^^^^^^^^^^^^^^^^^^^^^^^
  File "/home/airflow/.local/lib/python3.12/site-packages/airflow/operators/bash.py", line 249, in execute
    raise AirflowException(
airflow.exceptions.AirflowException: Bash command failed. The command returned a non-zero exit code 1.
[2025-10-25T13:52:04.491+0200] {local_task_job_runner.py:266} INFO - Task exited with return code 1
[2025-10-25T13:52:04.527+0200] {taskinstance.py:3900} INFO - 0 downstream tasks scheduled from follow-on schedule check
[2025-10-25T13:52:04.530+0200] {local_task_job_runner.py:245} INFO - ::endgroup::
