[2025-10-24T01:40:14.101+0200] {local_task_job_runner.py:123} INFO - ::group::Pre task execution logs
[2025-10-24T01:40:14.130+0200] {taskinstance.py:2612} INFO - Dependencies all met for dep_context=non-requeueable deps ti=<TaskInstance: dbt_hourly_refresh.run_dbt_models manual__2025-10-23T23:25:09.841026+00:00 [queued]>
[2025-10-24T01:40:14.142+0200] {taskinstance.py:2612} INFO - Dependencies all met for dep_context=requeueable deps ti=<TaskInstance: dbt_hourly_refresh.run_dbt_models manual__2025-10-23T23:25:09.841026+00:00 [queued]>
[2025-10-24T01:40:14.142+0200] {taskinstance.py:2865} INFO - Starting attempt 2 of 2
[2025-10-24T01:40:14.161+0200] {taskinstance.py:2888} INFO - Executing <Task(BashOperator): run_dbt_models> on 2025-10-23 23:25:09.841026+00:00
[2025-10-24T01:40:14.175+0200] {standard_task_runner.py:104} INFO - Running: ['***', 'tasks', 'run', 'dbt_hourly_refresh', 'run_dbt_models', 'manual__2025-10-23T23:25:09.841026+00:00', '--job-id', '34', '--raw', '--subdir', 'DAGS_FOLDER/dbt_hourly_refresh_dag.py', '--cfg-path', '/tmp/tmpyepiptrh']
[2025-10-24T01:40:14.180+0200] {standard_task_runner.py:105} INFO - Job 34: Subtask run_dbt_models
[2025-10-24T01:40:14.181+0200] {logging_mixin.py:190} WARNING - /home/***/.local/lib/python3.12/site-packages/***/task/task_runner/standard_task_runner.py:70 DeprecationWarning: This process (pid=259) is multi-threaded, use of fork() may lead to deadlocks in the child.
[2025-10-24T01:40:14.182+0200] {standard_task_runner.py:72} INFO - Started process 260 to run task
[2025-10-24T01:40:14.268+0200] {task_command.py:467} INFO - Running <TaskInstance: dbt_hourly_refresh.run_dbt_models manual__2025-10-23T23:25:09.841026+00:00 [running]> on host d22b34e12688
[2025-10-24T01:40:14.420+0200] {taskinstance.py:3131} INFO - Exporting env vars: AIRFLOW_CTX_DAG_OWNER='Aliostadi' AIRFLOW_CTX_DAG_ID='dbt_hourly_refresh' AIRFLOW_CTX_TASK_ID='run_dbt_models' AIRFLOW_CTX_EXECUTION_DATE='2025-10-23T23:25:09.841026+00:00' AIRFLOW_CTX_TRY_NUMBER='2' AIRFLOW_CTX_DAG_RUN_ID='manual__2025-10-23T23:25:09.841026+00:00'
[2025-10-24T01:40:14.421+0200] {taskinstance.py:731} INFO - ::endgroup::
[2025-10-24T01:40:14.499+0200] {subprocess.py:63} INFO - Tmp dir root location: /tmp
[2025-10-24T01:40:14.501+0200] {subprocess.py:75} INFO - Running command: ['/usr/bin/bash', '-c', 'cd /opt/***/dbt_project && dbt clean && dbt run --full-refresh']
[2025-10-24T01:40:14.516+0200] {subprocess.py:86} INFO - Output:
[2025-10-24T01:40:19.740+0200] {subprocess.py:93} INFO - [0m23:40:19  Running with dbt=1.8.3
[2025-10-24T01:40:20.025+0200] {subprocess.py:93} INFO - [0m23:40:20  Checking /opt/***/dbt_project/dbt_packages/*
[2025-10-24T01:40:20.025+0200] {subprocess.py:93} INFO - [0m23:40:20  Cleaned /opt/***/dbt_project/dbt_packages/*
[2025-10-24T01:40:20.026+0200] {subprocess.py:93} INFO - [0m23:40:20  Checking /opt/***/dbt_project/target/*
[2025-10-24T01:40:20.028+0200] {subprocess.py:93} INFO - [0m23:40:20  Cleaned /opt/***/dbt_project/target/*
[2025-10-24T01:40:20.028+0200] {subprocess.py:93} INFO - [0m23:40:20  Finished cleaning all paths.
[2025-10-24T01:40:24.392+0200] {subprocess.py:93} INFO - [0m23:40:24  Running with dbt=1.8.3
[2025-10-24T01:40:25.413+0200] {subprocess.py:93} INFO - [0m23:40:25  Registered adapter: postgres=1.8.2
[2025-10-24T01:40:25.881+0200] {subprocess.py:93} INFO - [0m23:40:25  Unable to do partial parsing because saved manifest not found. Starting full parse.
[2025-10-24T01:40:28.751+0200] {subprocess.py:93} INFO - [0m23:40:28  [[33mWARNING[0m]: Deprecated functionality
[2025-10-24T01:40:28.752+0200] {subprocess.py:93} INFO - The `tests` config has been renamed to `data_tests`. Please see
[2025-10-24T01:40:28.753+0200] {subprocess.py:93} INFO - https://docs.getdbt.com/docs/build/data-tests#new-data_tests-syntax for more
[2025-10-24T01:40:28.754+0200] {subprocess.py:93} INFO - information.
[2025-10-24T01:40:29.451+0200] {subprocess.py:93} INFO - [0m23:40:29  [[33mWARNING[0m]: Configuration paths exist in your dbt_project.yml file which do not apply to any resources.
[2025-10-24T01:40:29.453+0200] {subprocess.py:93} INFO - There are 1 unused configuration paths:
[2025-10-24T01:40:29.453+0200] {subprocess.py:93} INFO - - models.intermediters
[2025-10-24T01:40:29.808+0200] {subprocess.py:93} INFO - [0m23:40:29  Found 3 models, 6 data tests, 3 sources, 428 macros
[2025-10-24T01:40:29.812+0200] {subprocess.py:93} INFO - [0m23:40:29
[2025-10-24T01:40:30.006+0200] {subprocess.py:93} INFO - [0m23:40:30  Concurrency: 4 threads (target='dev')
[2025-10-24T01:40:30.007+0200] {subprocess.py:93} INFO - [0m23:40:30
[2025-10-24T01:40:30.027+0200] {subprocess.py:93} INFO - [0m23:40:30  1 of 3 START sql incremental model analytics.int_performance_station_hour ...... [RUN]
[2025-10-24T01:40:30.028+0200] {subprocess.py:93} INFO - [0m23:40:30  2 of 3 START sql incremental model analytics.int_quality_station_hour .......... [RUN]
[2025-10-24T01:40:30.060+0200] {subprocess.py:93} INFO - [0m23:40:30  [31mUnhandled error while executing [0m
[2025-10-24T01:40:30.060+0200] {subprocess.py:93} INFO - [Errno 13] Permission denied: '/opt/***/dbt_project/target/compiled/smt_project/models/intermediate/int_performance_station_hour.sql'
[2025-10-24T01:40:30.061+0200] {subprocess.py:93} INFO - [0m23:40:30  [31mUnhandled error while executing [0m
[2025-10-24T01:40:30.062+0200] {subprocess.py:93} INFO - [Errno 13] Permission denied: '/opt/***/dbt_project/target/compiled/smt_project/models/intermediate/int_quality_station_hour.sql'
[2025-10-24T01:40:30.077+0200] {subprocess.py:93} INFO - [0m23:40:30  1 of 3 ERROR creating sql incremental model analytics.int_performance_station_hour  [[31mERROR[0m in 0.05s]
[2025-10-24T01:40:30.079+0200] {subprocess.py:93} INFO - [0m23:40:30  2 of 3 ERROR creating sql incremental model analytics.int_quality_station_hour . [[31mERROR[0m in 0.05s]
[2025-10-24T01:40:30.087+0200] {subprocess.py:93} INFO - [0m23:40:30  3 of 3 SKIP relation analytics.int_quality_linewise_datehour ................... [[33mSKIP[0m]
[2025-10-24T01:40:30.111+0200] {subprocess.py:93} INFO - [0m23:40:30
[2025-10-24T01:40:30.112+0200] {subprocess.py:93} INFO - [0m23:40:30  Finished running 3 incremental models in 0 hours 0 minutes and 0.30 seconds (0.30s).
[2025-10-24T01:40:30.166+0200] {subprocess.py:93} INFO - [0m23:40:30
[2025-10-24T01:40:30.167+0200] {subprocess.py:93} INFO - [0m23:40:30  [31mCompleted with 2 errors and 0 warnings:[0m
[2025-10-24T01:40:30.168+0200] {subprocess.py:93} INFO - [0m23:40:30
[2025-10-24T01:40:30.169+0200] {subprocess.py:93} INFO - [0m23:40:30    [Errno 13] Permission denied: '/opt/***/dbt_project/target/compiled/smt_project/models/intermediate/int_performance_station_hour.sql'
[2025-10-24T01:40:30.169+0200] {subprocess.py:93} INFO - [0m23:40:30
[2025-10-24T01:40:30.170+0200] {subprocess.py:93} INFO - [0m23:40:30    [Errno 13] Permission denied: '/opt/***/dbt_project/target/compiled/smt_project/models/intermediate/int_quality_station_hour.sql'
[2025-10-24T01:40:30.170+0200] {subprocess.py:93} INFO - [0m23:40:30
[2025-10-24T01:40:30.171+0200] {subprocess.py:93} INFO - [0m23:40:30  Done. PASS=0 WARN=0 ERROR=2 SKIP=1 TOTAL=3
[2025-10-24T01:40:30.626+0200] {subprocess.py:97} INFO - Command exited with return code 1
[2025-10-24T01:40:30.656+0200] {taskinstance.py:3310} ERROR - Task failed with exception
Traceback (most recent call last):
  File "/home/airflow/.local/lib/python3.12/site-packages/airflow/models/taskinstance.py", line 767, in _execute_task
    result = _execute_callable(context=context, **execute_callable_kwargs)
             ^^^^^^^^^^^^^^^^^^^^^^^^^^^^^^^^^^^^^^^^^^^^^^^^^^^^^^^^^^^^^
  File "/home/airflow/.local/lib/python3.12/site-packages/airflow/models/taskinstance.py", line 733, in _execute_callable
    return ExecutionCallableRunner(
           ^^^^^^^^^^^^^^^^^^^^^^^^
  File "/home/airflow/.local/lib/python3.12/site-packages/airflow/utils/operator_helpers.py", line 252, in run
    return self.func(*args, **kwargs)
           ^^^^^^^^^^^^^^^^^^^^^^^^^^
  File "/home/airflow/.local/lib/python3.12/site-packages/airflow/models/baseoperator.py", line 406, in wrapper
    return func(self, *args, **kwargs)
           ^^^^^^^^^^^^^^^^^^^^^^^^^^^
  File "/home/airflow/.local/lib/python3.12/site-packages/airflow/operators/bash.py", line 249, in execute
    raise AirflowException(
airflow.exceptions.AirflowException: Bash command failed. The command returned a non-zero exit code 1.
[2025-10-24T01:40:30.666+0200] {taskinstance.py:1225} INFO - Marking task as FAILED. dag_id=dbt_hourly_refresh, task_id=run_dbt_models, run_id=manual__2025-10-23T23:25:09.841026+00:00, execution_date=20251023T232509, start_date=20251023T234014, end_date=20251023T234030
[2025-10-24T01:40:30.693+0200] {taskinstance.py:340} INFO - ::group::Post task execution logs
[2025-10-24T01:40:30.694+0200] {standard_task_runner.py:124} ERROR - Failed to execute job 34 for task run_dbt_models (Bash command failed. The command returned a non-zero exit code 1.; 260)
Traceback (most recent call last):
  File "/home/airflow/.local/lib/python3.12/site-packages/airflow/task/task_runner/standard_task_runner.py", line 117, in _start_by_fork
    ret = args.func(args, dag=self.dag)
          ^^^^^^^^^^^^^^^^^^^^^^^^^^^^^
  File "/home/airflow/.local/lib/python3.12/site-packages/airflow/cli/cli_config.py", line 49, in command
    return func(*args, **kwargs)
           ^^^^^^^^^^^^^^^^^^^^^
  File "/home/airflow/.local/lib/python3.12/site-packages/airflow/utils/cli.py", line 115, in wrapper
    return f(*args, **kwargs)
           ^^^^^^^^^^^^^^^^^^
  File "/home/airflow/.local/lib/python3.12/site-packages/airflow/cli/commands/task_command.py", line 483, in task_run
    task_return_code = _run_task_by_selected_method(args, _dag, ti)
                       ^^^^^^^^^^^^^^^^^^^^^^^^^^^^^^^^^^^^^^^^^^^^
  File "/home/airflow/.local/lib/python3.12/site-packages/airflow/cli/commands/task_command.py", line 256, in _run_task_by_selected_method
    return _run_raw_task(args, ti)
           ^^^^^^^^^^^^^^^^^^^^^^^
  File "/home/airflow/.local/lib/python3.12/site-packages/airflow/cli/commands/task_command.py", line 341, in _run_raw_task
    return ti._run_raw_task(
           ^^^^^^^^^^^^^^^^^
  File "/home/airflow/.local/lib/python3.12/site-packages/airflow/utils/session.py", line 97, in wrapper
    return func(*args, session=session, **kwargs)
           ^^^^^^^^^^^^^^^^^^^^^^^^^^^^^^^^^^^^^^
  File "/home/airflow/.local/lib/python3.12/site-packages/airflow/models/taskinstance.py", line 3004, in _run_raw_task
    return _run_raw_task(
           ^^^^^^^^^^^^^^
  File "/home/airflow/.local/lib/python3.12/site-packages/airflow/models/taskinstance.py", line 273, in _run_raw_task
    TaskInstance._execute_task_with_callbacks(
  File "/home/airflow/.local/lib/python3.12/site-packages/airflow/models/taskinstance.py", line 3158, in _execute_task_with_callbacks
    result = self._execute_task(context, task_orig)
             ^^^^^^^^^^^^^^^^^^^^^^^^^^^^^^^^^^^^^^
  File "/home/airflow/.local/lib/python3.12/site-packages/airflow/models/taskinstance.py", line 3182, in _execute_task
    return _execute_task(self, context, task_orig)
           ^^^^^^^^^^^^^^^^^^^^^^^^^^^^^^^^^^^^^^^
  File "/home/airflow/.local/lib/python3.12/site-packages/airflow/models/taskinstance.py", line 767, in _execute_task
    result = _execute_callable(context=context, **execute_callable_kwargs)
             ^^^^^^^^^^^^^^^^^^^^^^^^^^^^^^^^^^^^^^^^^^^^^^^^^^^^^^^^^^^^^
  File "/home/airflow/.local/lib/python3.12/site-packages/airflow/models/taskinstance.py", line 733, in _execute_callable
    return ExecutionCallableRunner(
           ^^^^^^^^^^^^^^^^^^^^^^^^
  File "/home/airflow/.local/lib/python3.12/site-packages/airflow/utils/operator_helpers.py", line 252, in run
    return self.func(*args, **kwargs)
           ^^^^^^^^^^^^^^^^^^^^^^^^^^
  File "/home/airflow/.local/lib/python3.12/site-packages/airflow/models/baseoperator.py", line 406, in wrapper
    return func(self, *args, **kwargs)
           ^^^^^^^^^^^^^^^^^^^^^^^^^^^
  File "/home/airflow/.local/lib/python3.12/site-packages/airflow/operators/bash.py", line 249, in execute
    raise AirflowException(
airflow.exceptions.AirflowException: Bash command failed. The command returned a non-zero exit code 1.
[2025-10-24T01:40:30.717+0200] {local_task_job_runner.py:266} INFO - Task exited with return code 1
[2025-10-24T01:40:30.743+0200] {taskinstance.py:3900} INFO - 0 downstream tasks scheduled from follow-on schedule check
[2025-10-24T01:40:30.746+0200] {local_task_job_runner.py:245} INFO - ::endgroup::
