[2025-10-24T01:25:11.920+0200] {local_task_job_runner.py:123} INFO - ::group::Pre task execution logs
[2025-10-24T01:25:11.996+0200] {taskinstance.py:2612} INFO - Dependencies all met for dep_context=non-requeueable deps ti=<TaskInstance: dbt_hourly_refresh.run_dbt_models manual__2025-10-23T23:25:09.841026+00:00 [queued]>
[2025-10-24T01:25:12.020+0200] {taskinstance.py:2612} INFO - Dependencies all met for dep_context=requeueable deps ti=<TaskInstance: dbt_hourly_refresh.run_dbt_models manual__2025-10-23T23:25:09.841026+00:00 [queued]>
[2025-10-24T01:25:12.021+0200] {taskinstance.py:2865} INFO - Starting attempt 1 of 2
[2025-10-24T01:25:12.073+0200] {taskinstance.py:2888} INFO - Executing <Task(BashOperator): run_dbt_models> on 2025-10-23 23:25:09.841026+00:00
[2025-10-24T01:25:12.102+0200] {standard_task_runner.py:104} INFO - Running: ['***', 'tasks', 'run', 'dbt_hourly_refresh', 'run_dbt_models', 'manual__2025-10-23T23:25:09.841026+00:00', '--job-id', '31', '--raw', '--subdir', 'DAGS_FOLDER/dbt_hourly_refresh_dag.py', '--cfg-path', '/tmp/tmpvt34mlnf']
[2025-10-24T01:25:12.115+0200] {standard_task_runner.py:105} INFO - Job 31: Subtask run_dbt_models
[2025-10-24T01:25:12.120+0200] {logging_mixin.py:190} WARNING - /home/***/.local/lib/python3.12/site-packages/***/task/task_runner/standard_task_runner.py:70 DeprecationWarning: This process (pid=357) is multi-threaded, use of fork() may lead to deadlocks in the child.
[2025-10-24T01:25:12.123+0200] {standard_task_runner.py:72} INFO - Started process 358 to run task
[2025-10-24T01:25:12.331+0200] {task_command.py:467} INFO - Running <TaskInstance: dbt_hourly_refresh.run_dbt_models manual__2025-10-23T23:25:09.841026+00:00 [running]> on host 5fbeed87b001
[2025-10-24T01:25:12.803+0200] {taskinstance.py:3131} INFO - Exporting env vars: AIRFLOW_CTX_DAG_OWNER='Aliostadi' AIRFLOW_CTX_DAG_ID='dbt_hourly_refresh' AIRFLOW_CTX_TASK_ID='run_dbt_models' AIRFLOW_CTX_EXECUTION_DATE='2025-10-23T23:25:09.841026+00:00' AIRFLOW_CTX_TRY_NUMBER='1' AIRFLOW_CTX_DAG_RUN_ID='manual__2025-10-23T23:25:09.841026+00:00'
[2025-10-24T01:25:12.807+0200] {taskinstance.py:731} INFO - ::endgroup::
[2025-10-24T01:25:12.975+0200] {subprocess.py:63} INFO - Tmp dir root location: /tmp
[2025-10-24T01:25:12.980+0200] {subprocess.py:75} INFO - Running command: ['/usr/bin/bash', '-c', 'cd /opt/***/dbt_project && dbt run']
[2025-10-24T01:25:13.018+0200] {subprocess.py:86} INFO - Output:
[2025-10-24T01:25:20.021+0200] {subprocess.py:93} INFO - [0m23:25:20  Running with dbt=1.8.3
[2025-10-24T01:25:20.762+0200] {subprocess.py:93} INFO - [0m23:25:20  Registered adapter: postgres=1.8.2
[2025-10-24T01:25:22.411+0200] {subprocess.py:93} INFO - [0m23:25:22  [[33mWARNING[0m]: Configuration paths exist in your dbt_project.yml file which do not apply to any resources.
[2025-10-24T01:25:22.412+0200] {subprocess.py:93} INFO - There are 1 unused configuration paths:
[2025-10-24T01:25:22.412+0200] {subprocess.py:93} INFO - - models.intermediters
[2025-10-24T01:25:22.679+0200] {subprocess.py:93} INFO - [0m23:25:22  Found 3 models, 6 data tests, 3 sources, 428 macros
[2025-10-24T01:25:22.685+0200] {subprocess.py:93} INFO - [0m23:25:22
[2025-10-24T01:25:23.078+0200] {subprocess.py:93} INFO - [0m23:25:23  Concurrency: 4 threads (target='dev')
[2025-10-24T01:25:23.080+0200] {subprocess.py:93} INFO - [0m23:25:23
[2025-10-24T01:25:23.115+0200] {subprocess.py:93} INFO - [0m23:25:23  1 of 3 START sql incremental model analytics.int_performance_station_hour ...... [RUN]
[2025-10-24T01:25:23.121+0200] {subprocess.py:93} INFO - [0m23:25:23  2 of 3 START sql incremental model analytics.int_quality_station_hour .......... [RUN]
[2025-10-24T01:25:25.524+0200] {subprocess.py:93} INFO - [0m23:25:25  2 of 3 ERROR creating sql incremental model analytics.int_quality_station_hour . [[31mERROR[0m in 2.39s]
[2025-10-24T01:25:25.548+0200] {subprocess.py:93} INFO - [0m23:25:25  3 of 3 SKIP relation analytics.int_quality_linewise_datehour ................... [[33mSKIP[0m]
[2025-10-24T01:25:25.741+0200] {subprocess.py:93} INFO - [0m23:25:25  1 of 3 OK created sql incremental model analytics.int_performance_station_hour . [[32mINSERT 0 8[0m in 2.62s]
[2025-10-24T01:25:25.899+0200] {subprocess.py:93} INFO - [0m23:25:25
[2025-10-24T01:25:25.900+0200] {subprocess.py:93} INFO - [0m23:25:25  Finished running 3 incremental models in 0 hours 0 minutes and 3.21 seconds (3.21s).
[2025-10-24T01:25:26.010+0200] {subprocess.py:93} INFO - [0m23:25:26
[2025-10-24T01:25:26.011+0200] {subprocess.py:93} INFO - [0m23:25:26  [31mCompleted with 1 error and 0 warnings:[0m
[2025-10-24T01:25:26.012+0200] {subprocess.py:93} INFO - [0m23:25:26
[2025-10-24T01:25:26.014+0200] {subprocess.py:93} INFO - [0m23:25:26    Database Error in model int_quality_station_hour (models/intermediate/int_quality_station_hour.sql)
[2025-10-24T01:25:26.015+0200] {subprocess.py:93} INFO -   aggregate functions are not allowed in WHERE
[2025-10-24T01:25:26.016+0200] {subprocess.py:93} INFO -   LINE 31:         WHERE date_created > (SELECT MAX(date_created) FROM ...
[2025-10-24T01:25:26.017+0200] {subprocess.py:93} INFO -                                                 ^
[2025-10-24T01:25:26.018+0200] {subprocess.py:93} INFO - [0m23:25:26
[2025-10-24T01:25:26.019+0200] {subprocess.py:93} INFO - [0m23:25:26  Done. PASS=1 WARN=0 ERROR=1 SKIP=1 TOTAL=3
[2025-10-24T01:25:26.882+0200] {subprocess.py:97} INFO - Command exited with return code 1
[2025-10-24T01:25:27.138+0200] {taskinstance.py:3310} ERROR - Task failed with exception
Traceback (most recent call last):
  File "/home/airflow/.local/lib/python3.12/site-packages/airflow/models/taskinstance.py", line 767, in _execute_task
    result = _execute_callable(context=context, **execute_callable_kwargs)
             ^^^^^^^^^^^^^^^^^^^^^^^^^^^^^^^^^^^^^^^^^^^^^^^^^^^^^^^^^^^^^
  File "/home/airflow/.local/lib/python3.12/site-packages/airflow/models/taskinstance.py", line 733, in _execute_callable
    return ExecutionCallableRunner(
           ^^^^^^^^^^^^^^^^^^^^^^^^
  File "/home/airflow/.local/lib/python3.12/site-packages/airflow/utils/operator_helpers.py", line 252, in run
    return self.func(*args, **kwargs)
           ^^^^^^^^^^^^^^^^^^^^^^^^^^
  File "/home/airflow/.local/lib/python3.12/site-packages/airflow/models/baseoperator.py", line 406, in wrapper
    return func(self, *args, **kwargs)
           ^^^^^^^^^^^^^^^^^^^^^^^^^^^
  File "/home/airflow/.local/lib/python3.12/site-packages/airflow/operators/bash.py", line 249, in execute
    raise AirflowException(
airflow.exceptions.AirflowException: Bash command failed. The command returned a non-zero exit code 1.
[2025-10-24T01:25:27.175+0200] {taskinstance.py:1225} INFO - Marking task as UP_FOR_RETRY. dag_id=dbt_hourly_refresh, task_id=run_dbt_models, run_id=manual__2025-10-23T23:25:09.841026+00:00, execution_date=20251023T232509, start_date=20251023T232511, end_date=20251023T232527
[2025-10-24T01:25:27.223+0200] {taskinstance.py:340} INFO - ::group::Post task execution logs
[2025-10-24T01:25:27.224+0200] {standard_task_runner.py:124} ERROR - Failed to execute job 31 for task run_dbt_models (Bash command failed. The command returned a non-zero exit code 1.; 358)
Traceback (most recent call last):
  File "/home/airflow/.local/lib/python3.12/site-packages/airflow/task/task_runner/standard_task_runner.py", line 117, in _start_by_fork
    ret = args.func(args, dag=self.dag)
          ^^^^^^^^^^^^^^^^^^^^^^^^^^^^^
  File "/home/airflow/.local/lib/python3.12/site-packages/airflow/cli/cli_config.py", line 49, in command
    return func(*args, **kwargs)
           ^^^^^^^^^^^^^^^^^^^^^
  File "/home/airflow/.local/lib/python3.12/site-packages/airflow/utils/cli.py", line 115, in wrapper
    return f(*args, **kwargs)
           ^^^^^^^^^^^^^^^^^^
  File "/home/airflow/.local/lib/python3.12/site-packages/airflow/cli/commands/task_command.py", line 483, in task_run
    task_return_code = _run_task_by_selected_method(args, _dag, ti)
                       ^^^^^^^^^^^^^^^^^^^^^^^^^^^^^^^^^^^^^^^^^^^^
  File "/home/airflow/.local/lib/python3.12/site-packages/airflow/cli/commands/task_command.py", line 256, in _run_task_by_selected_method
    return _run_raw_task(args, ti)
           ^^^^^^^^^^^^^^^^^^^^^^^
  File "/home/airflow/.local/lib/python3.12/site-packages/airflow/cli/commands/task_command.py", line 341, in _run_raw_task
    return ti._run_raw_task(
           ^^^^^^^^^^^^^^^^^
  File "/home/airflow/.local/lib/python3.12/site-packages/airflow/utils/session.py", line 97, in wrapper
    return func(*args, session=session, **kwargs)
           ^^^^^^^^^^^^^^^^^^^^^^^^^^^^^^^^^^^^^^
  File "/home/airflow/.local/lib/python3.12/site-packages/airflow/models/taskinstance.py", line 3004, in _run_raw_task
    return _run_raw_task(
           ^^^^^^^^^^^^^^
  File "/home/airflow/.local/lib/python3.12/site-packages/airflow/models/taskinstance.py", line 273, in _run_raw_task
    TaskInstance._execute_task_with_callbacks(
  File "/home/airflow/.local/lib/python3.12/site-packages/airflow/models/taskinstance.py", line 3158, in _execute_task_with_callbacks
    result = self._execute_task(context, task_orig)
             ^^^^^^^^^^^^^^^^^^^^^^^^^^^^^^^^^^^^^^
  File "/home/airflow/.local/lib/python3.12/site-packages/airflow/models/taskinstance.py", line 3182, in _execute_task
    return _execute_task(self, context, task_orig)
           ^^^^^^^^^^^^^^^^^^^^^^^^^^^^^^^^^^^^^^^
  File "/home/airflow/.local/lib/python3.12/site-packages/airflow/models/taskinstance.py", line 767, in _execute_task
    result = _execute_callable(context=context, **execute_callable_kwargs)
             ^^^^^^^^^^^^^^^^^^^^^^^^^^^^^^^^^^^^^^^^^^^^^^^^^^^^^^^^^^^^^
  File "/home/airflow/.local/lib/python3.12/site-packages/airflow/models/taskinstance.py", line 733, in _execute_callable
    return ExecutionCallableRunner(
           ^^^^^^^^^^^^^^^^^^^^^^^^
  File "/home/airflow/.local/lib/python3.12/site-packages/airflow/utils/operator_helpers.py", line 252, in run
    return self.func(*args, **kwargs)
           ^^^^^^^^^^^^^^^^^^^^^^^^^^
  File "/home/airflow/.local/lib/python3.12/site-packages/airflow/models/baseoperator.py", line 406, in wrapper
    return func(self, *args, **kwargs)
           ^^^^^^^^^^^^^^^^^^^^^^^^^^^
  File "/home/airflow/.local/lib/python3.12/site-packages/airflow/operators/bash.py", line 249, in execute
    raise AirflowException(
airflow.exceptions.AirflowException: Bash command failed. The command returned a non-zero exit code 1.
[2025-10-24T01:25:27.271+0200] {local_task_job_runner.py:266} INFO - Task exited with return code 1
[2025-10-24T01:25:27.316+0200] {taskinstance.py:3900} INFO - 0 downstream tasks scheduled from follow-on schedule check
[2025-10-24T01:25:27.319+0200] {local_task_job_runner.py:245} INFO - ::endgroup::
